[2016-08-17 15:54:59,450] [Thread-8:1056] [django.request:170] [base:get_response] [WARNING]- Not Found: /favicon.ico
[2016-09-22 19:00:48,176] [Thread-7:4732] [django.request:170] [base:get_response] [WARNING]- Not Found: /favicon.ico
[2016-10-12 16:04:46,082] [Thread-6:3896] [django.request:170] [base:get_response] [WARNING]- Not Found: /favicon.ico
[2016-10-12 18:58:37,898] [Thread-180:1744] [django.request:256] [base:handle_uncaught_exception] [ERROR]- Internal Server Error: /
Traceback (most recent call last):
  File "C:\Python27\lib\site-packages\django-1.8.14-py2.7.egg\django\core\handlers\base.py", line 132, in get_response
    response = wrapped_callback(request, *callback_args, **callback_kwargs)
  File "D:\PycharmProjects\fec\apps\ec\views.py", line 32, in prod_list
    context_dict)
  File "C:\Python27\lib\site-packages\django-1.8.14-py2.7.egg\django\shortcuts.py", line 67, in render
    template_name, context, request=request, using=using)
  File "C:\Python27\lib\site-packages\django-1.8.14-py2.7.egg\django\template\loader.py", line 99, in render_to_string
    return template.render(context, request)
  File "C:\Python27\lib\site-packages\django-1.8.14-py2.7.egg\django\template\backends\django.py", line 74, in render
    return self.template.render(context)
  File "C:\Python27\lib\site-packages\django-1.8.14-py2.7.egg\django\template\base.py", line 210, in render
    return self._render(context)
  File "C:\Python27\lib\site-packages\django-1.8.14-py2.7.egg\django\template\base.py", line 202, in _render
    return self.nodelist.render(context)
  File "C:\Python27\lib\site-packages\django-1.8.14-py2.7.egg\django\template\base.py", line 905, in render
    bit = self.render_node(node, context)
  File "C:\Python27\lib\site-packages\django-1.8.14-py2.7.egg\django\template\debug.py", line 79, in render_node
    return node.render(context)
  File "C:\Python27\lib\site-packages\django-1.8.14-py2.7.egg\django\template\loader_tags.py", line 135, in render
    return compiled_parent._render(context)
  File "C:\Python27\lib\site-packages\django-1.8.14-py2.7.egg\django\template\base.py", line 202, in _render
    return self.nodelist.render(context)
  File "C:\Python27\lib\site-packages\django-1.8.14-py2.7.egg\django\template\base.py", line 905, in render
    bit = self.render_node(node, context)
  File "C:\Python27\lib\site-packages\django-1.8.14-py2.7.egg\django\template\debug.py", line 79, in render_node
    return node.render(context)
  File "C:\Python27\lib\site-packages\django-1.8.14-py2.7.egg\django\template\loader_tags.py", line 135, in render
    return compiled_parent._render(context)
  File "C:\Python27\lib\site-packages\django-1.8.14-py2.7.egg\django\template\base.py", line 202, in _render
    return self.nodelist.render(context)
  File "C:\Python27\lib\site-packages\django-1.8.14-py2.7.egg\django\template\base.py", line 905, in render
    bit = self.render_node(node, context)
  File "C:\Python27\lib\site-packages\django-1.8.14-py2.7.egg\django\template\debug.py", line 79, in render_node
    return node.render(context)
  File "C:\Python27\lib\site-packages\django-1.8.14-py2.7.egg\django\template\loader_tags.py", line 65, in render
    result = block.nodelist.render(context)
  File "C:\Python27\lib\site-packages\django-1.8.14-py2.7.egg\django\template\base.py", line 905, in render
    bit = self.render_node(node, context)
  File "C:\Python27\lib\site-packages\django-1.8.14-py2.7.egg\django\template\debug.py", line 79, in render_node
    return node.render(context)
  File "C:\Python27\lib\site-packages\django-1.8.14-py2.7.egg\django\template\loader_tags.py", line 65, in render
    result = block.nodelist.render(context)
  File "C:\Python27\lib\site-packages\django-1.8.14-py2.7.egg\django\template\base.py", line 905, in render
    bit = self.render_node(node, context)
  File "C:\Python27\lib\site-packages\django-1.8.14-py2.7.egg\django\template\debug.py", line 79, in render_node
    return node.render(context)
  File "C:\Python27\lib\site-packages\django-1.8.14-py2.7.egg\django\template\defaulttags.py", line 162, in render
    len_values = len(values)
  File "C:\Python27\lib\site-packages\django-1.8.14-py2.7.egg\django\db\models\query.py", line 144, in __len__
    self._fetch_all()
  File "C:\Python27\lib\site-packages\django-1.8.14-py2.7.egg\django\db\models\query.py", line 965, in _fetch_all
    self._result_cache = list(self.iterator())
  File "C:\Python27\lib\site-packages\django-1.8.14-py2.7.egg\django\db\models\query.py", line 238, in iterator
    results = compiler.execute_sql()
  File "C:\Python27\lib\site-packages\django-1.8.14-py2.7.egg\django\db\models\sql\compiler.py", line 840, in execute_sql
    cursor.execute(sql, params)
  File "C:\Python27\lib\site-packages\django-1.8.14-py2.7.egg\django\db\backends\utils.py", line 79, in execute
    return super(CursorDebugWrapper, self).execute(sql, params)
  File "C:\Python27\lib\site-packages\django-1.8.14-py2.7.egg\django\db\backends\utils.py", line 64, in execute
    return self.cursor.execute(sql, params)
  File "C:\Python27\lib\site-packages\django-1.8.14-py2.7.egg\django\db\utils.py", line 98, in __exit__
    six.reraise(dj_exc_type, dj_exc_value, traceback)
  File "C:\Python27\lib\site-packages\django-1.8.14-py2.7.egg\django\db\backends\utils.py", line 64, in execute
    return self.cursor.execute(sql, params)
  File "C:\Python27\lib\site-packages\django-1.8.14-py2.7.egg\django\db\backends\mysql\base.py", line 124, in execute
    return self.cursor.execute(query, args)
  File "C:\Python27\lib\site-packages\MySQLdb\cursors.py", line 174, in execute
    self.errorhandler(self, exc, value)
  File "C:\Python27\lib\site-packages\MySQLdb\connections.py", line 36, in defaulterrorhandler
    raise errorclass, errorvalue
OperationalError: (2006, 'MySQL server has gone away')
[2016-10-12 19:58:28,844] [Thread-25:76] [django.request:256] [base:handle_uncaught_exception] [ERROR]- Internal Server Error: /cart/
Traceback (most recent call last):
  File "C:\Python27\lib\site-packages\django-1.8.14-py2.7.egg\django\core\handlers\base.py", line 132, in get_response
    response = wrapped_callback(request, *callback_args, **callback_kwargs)
  File "C:\Python27\lib\site-packages\django-1.8.14-py2.7.egg\django\contrib\auth\decorators.py", line 22, in _wrapped_view
    return view_func(request, *args, **kwargs)
  File "D:\PycharmProjects\fec\apps\ec\views.py", line 130, in get_cart_info
    context_dict = get_cart_detail(cust_id)
  File "C:\Python27\lib\site-packages\django-1.8.14-py2.7.egg\django\contrib\auth\decorators.py", line 21, in _wrapped_view
    if test_func(request.user):
AttributeError: 'long' object has no attribute 'user'
[2016-10-12 19:58:36,048] [Thread-26:3348] [django.request:256] [base:handle_uncaught_exception] [ERROR]- Internal Server Error: /cart/
Traceback (most recent call last):
  File "C:\Python27\lib\site-packages\django-1.8.14-py2.7.egg\django\core\handlers\base.py", line 132, in get_response
    response = wrapped_callback(request, *callback_args, **callback_kwargs)
  File "C:\Python27\lib\site-packages\django-1.8.14-py2.7.egg\django\contrib\auth\decorators.py", line 22, in _wrapped_view
    return view_func(request, *args, **kwargs)
  File "D:\PycharmProjects\fec\apps\ec\views.py", line 130, in get_cart_info
    context_dict = get_cart_detail(cust_id)
  File "C:\Python27\lib\site-packages\django-1.8.14-py2.7.egg\django\contrib\auth\decorators.py", line 21, in _wrapped_view
    if test_func(request.user):
AttributeError: 'long' object has no attribute 'user'
[2016-10-12 19:58:58,838] [Thread-27:1816] [django.request:256] [base:handle_uncaught_exception] [ERROR]- Internal Server Error: /cart/
Traceback (most recent call last):
  File "C:\Python27\lib\site-packages\django-1.8.14-py2.7.egg\django\core\handlers\base.py", line 132, in get_response
    response = wrapped_callback(request, *callback_args, **callback_kwargs)
  File "C:\Python27\lib\site-packages\django-1.8.14-py2.7.egg\django\contrib\auth\decorators.py", line 22, in _wrapped_view
    return view_func(request, *args, **kwargs)
  File "D:\PycharmProjects\fec\apps\ec\views.py", line 130, in get_cart_info
    context_dict = get_cart_detail(cust_id)
  File "C:\Python27\lib\site-packages\django-1.8.14-py2.7.egg\django\contrib\auth\decorators.py", line 21, in _wrapped_view
    if test_func(request.user):
AttributeError: 'long' object has no attribute 'user'
[2016-10-12 19:59:41,144] [Thread-2:4584] [django.request:256] [base:handle_uncaught_exception] [ERROR]- Internal Server Error: /cart/
Traceback (most recent call last):
  File "C:\Python27\lib\site-packages\django-1.8.14-py2.7.egg\django\core\handlers\base.py", line 132, in get_response
    response = wrapped_callback(request, *callback_args, **callback_kwargs)
  File "D:\PycharmProjects\fec\apps\ec\views.py", line 129, in get_cart_info
    context_dict = get_cart_detail(cust_id)
  File "C:\Python27\lib\site-packages\django-1.8.14-py2.7.egg\django\contrib\auth\decorators.py", line 21, in _wrapped_view
    if test_func(request.user):
AttributeError: 'long' object has no attribute 'user'
[2016-10-12 19:59:56,815] [Thread-4:684] [django.request:256] [base:handle_uncaught_exception] [ERROR]- Internal Server Error: /cart/
Traceback (most recent call last):
  File "C:\Python27\lib\site-packages\django-1.8.14-py2.7.egg\django\core\handlers\base.py", line 132, in get_response
    response = wrapped_callback(request, *callback_args, **callback_kwargs)
  File "D:\PycharmProjects\fec\apps\ec\views.py", line 129, in get_cart_info
    context_dict = get_cart_detail(cust_id)
  File "C:\Python27\lib\site-packages\django-1.8.14-py2.7.egg\django\contrib\auth\decorators.py", line 21, in _wrapped_view
    if test_func(request.user):
AttributeError: 'long' object has no attribute 'user'
[2016-10-12 20:09:56,920] [Thread-2:4720] [django.request:256] [base:handle_uncaught_exception] [ERROR]- Internal Server Error: /cart/
Traceback (most recent call last):
  File "C:\Python27\lib\site-packages\django-1.8.14-py2.7.egg\django\core\handlers\base.py", line 132, in get_response
    response = wrapped_callback(request, *callback_args, **callback_kwargs)
  File "D:\PycharmProjects\fec\apps\ec\views.py", line 129, in get_cart_info
    context_dict = get_cart_detail(cust_id)
  File "C:\Python27\lib\site-packages\django-1.8.14-py2.7.egg\django\contrib\auth\decorators.py", line 21, in _wrapped_view
    if test_func(request.user):
AttributeError: 'long' object has no attribute 'user'
[2016-10-12 20:11:59,743] [Thread-3:4540] [django.request:256] [base:handle_uncaught_exception] [ERROR]- Internal Server Error: /cart/
Traceback (most recent call last):
  File "C:\Python27\lib\site-packages\django-1.8.14-py2.7.egg\django\core\handlers\base.py", line 132, in get_response
    response = wrapped_callback(request, *callback_args, **callback_kwargs)
  File "D:\PycharmProjects\fec\apps\ec\views.py", line 129, in get_cart_info
    context_dict = get_cart_detail(cust_id)
  File "C:\Python27\lib\site-packages\django-1.8.14-py2.7.egg\django\contrib\auth\decorators.py", line 21, in _wrapped_view
    if test_func(request.user):
AttributeError: 'long' object has no attribute 'user'
[2016-10-12 20:12:33,691] [Thread-4:4584] [django.request:256] [base:handle_uncaught_exception] [ERROR]- Internal Server Error: /cart/
Traceback (most recent call last):
  File "C:\Python27\lib\site-packages\django-1.8.14-py2.7.egg\django\core\handlers\base.py", line 132, in get_response
    response = wrapped_callback(request, *callback_args, **callback_kwargs)
  File "D:\PycharmProjects\fec\apps\ec\views.py", line 129, in get_cart_info
    context_dict = get_cart_detail(cust_id)
  File "C:\Python27\lib\site-packages\django-1.8.14-py2.7.egg\django\contrib\auth\decorators.py", line 21, in _wrapped_view
    if test_func(request.user):
AttributeError: 'long' object has no attribute 'user'
[2016-10-12 20:44:27,515] [Thread-11:2052] [django.request:256] [base:handle_uncaught_exception] [ERROR]- Internal Server Error: /cart/
Traceback (most recent call last):
  File "C:\Python27\lib\site-packages\django-1.8.14-py2.7.egg\django\core\handlers\base.py", line 132, in get_response
    response = wrapped_callback(request, *callback_args, **callback_kwargs)
  File "C:\Python27\lib\site-packages\django-1.8.14-py2.7.egg\django\contrib\auth\decorators.py", line 22, in _wrapped_view
    return view_func(request, *args, **kwargs)
  File "D:\PycharmProjects\fec\apps\ec\views.py", line 133, in get_cart_info
    context_dict)
  File "C:\Python27\lib\site-packages\django-1.8.14-py2.7.egg\django\shortcuts.py", line 67, in render
    template_name, context, request=request, using=using)
  File "C:\Python27\lib\site-packages\django-1.8.14-py2.7.egg\django\template\loader.py", line 98, in render_to_string
    template = get_template(template_name, using=using)
  File "C:\Python27\lib\site-packages\django-1.8.14-py2.7.egg\django\template\loader.py", line 35, in get_template
    return engine.get_template(template_name, dirs)
  File "C:\Python27\lib\site-packages\django-1.8.14-py2.7.egg\django\template\backends\django.py", line 30, in get_template
    return Template(self.engine.get_template(template_name, dirs))
  File "C:\Python27\lib\site-packages\django-1.8.14-py2.7.egg\django\template\engine.py", line 167, in get_template
    template, origin = self.find_template(template_name, dirs)
  File "C:\Python27\lib\site-packages\django-1.8.14-py2.7.egg\django\template\engine.py", line 141, in find_template
    source, display_name = loader(name, dirs)
  File "C:\Python27\lib\site-packages\django-1.8.14-py2.7.egg\django\template\loaders\base.py", line 13, in __call__
    return self.load_template(template_name, template_dirs)
  File "C:\Python27\lib\site-packages\django-1.8.14-py2.7.egg\django\template\loaders\base.py", line 23, in load_template
    template = Template(source, origin, template_name, self.engine)
  File "C:\Python27\lib\site-packages\django-1.8.14-py2.7.egg\django\template\base.py", line 191, in __init__
    self.nodelist = engine.compile_string(template_string, origin)
  File "C:\Python27\lib\site-packages\django-1.8.14-py2.7.egg\django\template\engine.py", line 261, in compile_string
    return parser.parse()
  File "C:\Python27\lib\site-packages\django-1.8.14-py2.7.egg\django\template\base.py", line 342, in parse
    compiled_result = compile_func(self, token)
  File "C:\Python27\lib\site-packages\django-1.8.14-py2.7.egg\django\template\loader_tags.py", line 210, in do_extends
    nodelist = parser.parse()
  File "C:\Python27\lib\site-packages\django-1.8.14-py2.7.egg\django\template\base.py", line 342, in parse
    compiled_result = compile_func(self, token)
  File "C:\Python27\lib\site-packages\django-1.8.14-py2.7.egg\django\template\loader_tags.py", line 184, in do_block
    nodelist = parser.parse(('endblock',))
  File "C:\Python27\lib\site-packages\django-1.8.14-py2.7.egg\django\template\base.py", line 342, in parse
    compiled_result = compile_func(self, token)
  File "C:\Python27\lib\site-packages\django-1.8.14-py2.7.egg\django\template\defaulttags.py", line 1440, in url
    viewname = parser.compile_filter(bits[1])
  File "C:\Python27\lib\site-packages\django-1.8.14-py2.7.egg\django\template\base.py", line 424, in compile_filter
    return FilterExpression(token, self)
  File "C:\Python27\lib\site-packages\django-1.8.14-py2.7.egg\django\template\base.py", line 640, in __init__
    "from '%s'" % (token[upto:], token))
TemplateSyntaxError: Could not parse the remainder: ':checkout' from 'ec:checkout'
[2016-10-12 20:46:46,040] [Thread-17:4256] [django.request:256] [base:handle_uncaught_exception] [ERROR]- Internal Server Error: /cart/
Traceback (most recent call last):
  File "C:\Python27\lib\site-packages\django-1.8.14-py2.7.egg\django\core\handlers\base.py", line 132, in get_response
    response = wrapped_callback(request, *callback_args, **callback_kwargs)
  File "C:\Python27\lib\site-packages\django-1.8.14-py2.7.egg\django\contrib\auth\decorators.py", line 22, in _wrapped_view
    return view_func(request, *args, **kwargs)
  File "D:\PycharmProjects\fec\apps\ec\views.py", line 133, in get_cart_info
    context_dict)
  File "C:\Python27\lib\site-packages\django-1.8.14-py2.7.egg\django\shortcuts.py", line 67, in render
    template_name, context, request=request, using=using)
  File "C:\Python27\lib\site-packages\django-1.8.14-py2.7.egg\django\template\loader.py", line 99, in render_to_string
    return template.render(context, request)
  File "C:\Python27\lib\site-packages\django-1.8.14-py2.7.egg\django\template\backends\django.py", line 74, in render
    return self.template.render(context)
  File "C:\Python27\lib\site-packages\django-1.8.14-py2.7.egg\django\template\base.py", line 210, in render
    return self._render(context)
  File "C:\Python27\lib\site-packages\django-1.8.14-py2.7.egg\django\template\base.py", line 202, in _render
    return self.nodelist.render(context)
  File "C:\Python27\lib\site-packages\django-1.8.14-py2.7.egg\django\template\base.py", line 905, in render
    bit = self.render_node(node, context)
  File "C:\Python27\lib\site-packages\django-1.8.14-py2.7.egg\django\template\debug.py", line 79, in render_node
    return node.render(context)
  File "C:\Python27\lib\site-packages\django-1.8.14-py2.7.egg\django\template\loader_tags.py", line 135, in render
    return compiled_parent._render(context)
  File "C:\Python27\lib\site-packages\django-1.8.14-py2.7.egg\django\template\base.py", line 202, in _render
    return self.nodelist.render(context)
  File "C:\Python27\lib\site-packages\django-1.8.14-py2.7.egg\django\template\base.py", line 905, in render
    bit = self.render_node(node, context)
  File "C:\Python27\lib\site-packages\django-1.8.14-py2.7.egg\django\template\debug.py", line 79, in render_node
    return node.render(context)
  File "C:\Python27\lib\site-packages\django-1.8.14-py2.7.egg\django\template\loader_tags.py", line 135, in render
    return compiled_parent._render(context)
  File "C:\Python27\lib\site-packages\django-1.8.14-py2.7.egg\django\template\base.py", line 202, in _render
    return self.nodelist.render(context)
  File "C:\Python27\lib\site-packages\django-1.8.14-py2.7.egg\django\template\base.py", line 905, in render
    bit = self.render_node(node, context)
  File "C:\Python27\lib\site-packages\django-1.8.14-py2.7.egg\django\template\debug.py", line 79, in render_node
    return node.render(context)
  File "C:\Python27\lib\site-packages\django-1.8.14-py2.7.egg\django\template\loader_tags.py", line 65, in render
    result = block.nodelist.render(context)
  File "C:\Python27\lib\site-packages\django-1.8.14-py2.7.egg\django\template\base.py", line 905, in render
    bit = self.render_node(node, context)
  File "C:\Python27\lib\site-packages\django-1.8.14-py2.7.egg\django\template\debug.py", line 79, in render_node
    return node.render(context)
  File "C:\Python27\lib\site-packages\django-1.8.14-py2.7.egg\django\template\loader_tags.py", line 65, in render
    result = block.nodelist.render(context)
  File "C:\Python27\lib\site-packages\django-1.8.14-py2.7.egg\django\template\base.py", line 905, in render
    bit = self.render_node(node, context)
  File "C:\Python27\lib\site-packages\django-1.8.14-py2.7.egg\django\template\debug.py", line 79, in render_node
    return node.render(context)
  File "C:\Python27\lib\site-packages\django-1.8.14-py2.7.egg\django\template\defaulttags.py", line 507, in render
    six.reraise(*exc_info)
  File "C:\Python27\lib\site-packages\django-1.8.14-py2.7.egg\django\template\defaulttags.py", line 493, in render
    url = reverse(view_name, args=args, kwargs=kwargs, current_app=current_app)
  File "C:\Python27\lib\site-packages\django-1.8.14-py2.7.egg\django\core\urlresolvers.py", line 578, in reverse
    return force_text(iri_to_uri(resolver._reverse_with_prefix(view, prefix, *args, **kwargs)))
  File "C:\Python27\lib\site-packages\django-1.8.14-py2.7.egg\django\core\urlresolvers.py", line 495, in _reverse_with_prefix
    (lookup_view_s, args, kwargs, len(patterns), patterns))
NoReverseMatch: Reverse for 'checkout' with arguments '()' and keyword arguments '{}' not found. 0 pattern(s) tried: []
[2016-10-12 20:49:25,977] [Thread-2:3636] [django.request:256] [base:handle_uncaught_exception] [ERROR]- Internal Server Error: /cart/
Traceback (most recent call last):
  File "C:\Python27\lib\site-packages\django-1.8.14-py2.7.egg\django\core\handlers\base.py", line 132, in get_response
    response = wrapped_callback(request, *callback_args, **callback_kwargs)
  File "C:\Python27\lib\site-packages\django-1.8.14-py2.7.egg\django\contrib\auth\decorators.py", line 22, in _wrapped_view
    return view_func(request, *args, **kwargs)
  File "D:\PycharmProjects\fec\apps\ec\views.py", line 133, in get_cart_info
    context_dict)
  File "C:\Python27\lib\site-packages\django-1.8.14-py2.7.egg\django\shortcuts.py", line 67, in render
    template_name, context, request=request, using=using)
  File "C:\Python27\lib\site-packages\django-1.8.14-py2.7.egg\django\template\loader.py", line 99, in render_to_string
    return template.render(context, request)
  File "C:\Python27\lib\site-packages\django-1.8.14-py2.7.egg\django\template\backends\django.py", line 74, in render
    return self.template.render(context)
  File "C:\Python27\lib\site-packages\django-1.8.14-py2.7.egg\django\template\base.py", line 210, in render
    return self._render(context)
  File "C:\Python27\lib\site-packages\django-1.8.14-py2.7.egg\django\template\base.py", line 202, in _render
    return self.nodelist.render(context)
  File "C:\Python27\lib\site-packages\django-1.8.14-py2.7.egg\django\template\base.py", line 905, in render
    bit = self.render_node(node, context)
  File "C:\Python27\lib\site-packages\django-1.8.14-py2.7.egg\django\template\debug.py", line 79, in render_node
    return node.render(context)
  File "C:\Python27\lib\site-packages\django-1.8.14-py2.7.egg\django\template\loader_tags.py", line 135, in render
    return compiled_parent._render(context)
  File "C:\Python27\lib\site-packages\django-1.8.14-py2.7.egg\django\template\base.py", line 202, in _render
    return self.nodelist.render(context)
  File "C:\Python27\lib\site-packages\django-1.8.14-py2.7.egg\django\template\base.py", line 905, in render
    bit = self.render_node(node, context)
  File "C:\Python27\lib\site-packages\django-1.8.14-py2.7.egg\django\template\debug.py", line 79, in render_node
    return node.render(context)
  File "C:\Python27\lib\site-packages\django-1.8.14-py2.7.egg\django\template\loader_tags.py", line 135, in render
    return compiled_parent._render(context)
  File "C:\Python27\lib\site-packages\django-1.8.14-py2.7.egg\django\template\base.py", line 202, in _render
    return self.nodelist.render(context)
  File "C:\Python27\lib\site-packages\django-1.8.14-py2.7.egg\django\template\base.py", line 905, in render
    bit = self.render_node(node, context)
  File "C:\Python27\lib\site-packages\django-1.8.14-py2.7.egg\django\template\debug.py", line 79, in render_node
    return node.render(context)
  File "C:\Python27\lib\site-packages\django-1.8.14-py2.7.egg\django\template\loader_tags.py", line 65, in render
    result = block.nodelist.render(context)
  File "C:\Python27\lib\site-packages\django-1.8.14-py2.7.egg\django\template\base.py", line 905, in render
    bit = self.render_node(node, context)
  File "C:\Python27\lib\site-packages\django-1.8.14-py2.7.egg\django\template\debug.py", line 79, in render_node
    return node.render(context)
  File "C:\Python27\lib\site-packages\django-1.8.14-py2.7.egg\django\template\loader_tags.py", line 65, in render
    result = block.nodelist.render(context)
  File "C:\Python27\lib\site-packages\django-1.8.14-py2.7.egg\django\template\base.py", line 905, in render
    bit = self.render_node(node, context)
  File "C:\Python27\lib\site-packages\django-1.8.14-py2.7.egg\django\template\debug.py", line 79, in render_node
    return node.render(context)
  File "C:\Python27\lib\site-packages\django-1.8.14-py2.7.egg\django\template\defaulttags.py", line 507, in render
    six.reraise(*exc_info)
  File "C:\Python27\lib\site-packages\django-1.8.14-py2.7.egg\django\template\defaulttags.py", line 493, in render
    url = reverse(view_name, args=args, kwargs=kwargs, current_app=current_app)
  File "C:\Python27\lib\site-packages\django-1.8.14-py2.7.egg\django\core\urlresolvers.py", line 578, in reverse
    return force_text(iri_to_uri(resolver._reverse_with_prefix(view, prefix, *args, **kwargs)))
  File "C:\Python27\lib\site-packages\django-1.8.14-py2.7.egg\django\core\urlresolvers.py", line 495, in _reverse_with_prefix
    (lookup_view_s, args, kwargs, len(patterns), patterns))
NoReverseMatch: Reverse for 'checkout' with arguments '()' and keyword arguments '{}' not found. 0 pattern(s) tried: []
[2016-10-12 20:52:13,805] [Thread-11:180] [django.request:98] [csrf:_reject] [WARNING]- Forbidden (CSRF token missing or incorrect.): /checkout/
[2016-10-12 20:53:25,526] [Thread-24:4640] [django.request:256] [base:handle_uncaught_exception] [ERROR]- Internal Server Error: /checkout/
Traceback (most recent call last):
  File "C:\Python27\lib\site-packages\django-1.8.14-py2.7.egg\django\core\handlers\base.py", line 132, in get_response
    response = wrapped_callback(request, *callback_args, **callback_kwargs)
  File "C:\Python27\lib\site-packages\django-1.8.14-py2.7.egg\django\contrib\auth\decorators.py", line 22, in _wrapped_view
    return view_func(request, *args, **kwargs)
  File "D:\PycharmProjects\fec\apps\ec\views.py", line 195, in checkout
    context_dict)
  File "C:\Python27\lib\site-packages\django-1.8.14-py2.7.egg\django\shortcuts.py", line 67, in render
    template_name, context, request=request, using=using)
  File "C:\Python27\lib\site-packages\django-1.8.14-py2.7.egg\django\template\loader.py", line 99, in render_to_string
    return template.render(context, request)
  File "C:\Python27\lib\site-packages\django-1.8.14-py2.7.egg\django\template\backends\django.py", line 72, in render
    context = make_context(context, request)
  File "C:\Python27\lib\site-packages\django-1.8.14-py2.7.egg\django\template\context.py", line 272, in make_context
    context.push(original_context)
  File "C:\Python27\lib\site-packages\django-1.8.14-py2.7.egg\django\template\context.py", line 55, in push
    return ContextDict(self, *args, **kwargs)
  File "C:\Python27\lib\site-packages\django-1.8.14-py2.7.egg\django\template\context.py", line 20, in __init__
    super(ContextDict, self).__init__(*args, **kwargs)
ValueError: dictionary update sequence element #0 has length 1; 2 is required
[2016-10-13 16:23:18,321] [Thread-9:2672] [django.request:170] [base:get_response] [WARNING]- Not Found: /favicon.ico
[2016-10-14 11:26:56,562] [Thread-7:3276] [django.request:256] [base:handle_uncaught_exception] [ERROR]- Internal Server Error: /checkout/
Traceback (most recent call last):
  File "C:\Python27\lib\site-packages\django-1.8.14-py2.7.egg\django\core\handlers\base.py", line 132, in get_response
    response = wrapped_callback(request, *callback_args, **callback_kwargs)
  File "C:\Python27\lib\site-packages\django-1.8.14-py2.7.egg\django\contrib\auth\decorators.py", line 21, in _wrapped_view
    if test_func(request.user):
  File "C:\Python27\lib\site-packages\django-1.8.14-py2.7.egg\django\contrib\auth\decorators.py", line 45, in <lambda>
    lambda u: u.is_authenticated(),
  File "C:\Python27\lib\site-packages\django-1.8.14-py2.7.egg\django\utils\functional.py", line 225, in inner
    self._setup()
  File "C:\Python27\lib\site-packages\django-1.8.14-py2.7.egg\django\utils\functional.py", line 376, in _setup
    self._wrapped = self._setupfunc()
  File "C:\Python27\lib\site-packages\django-1.8.14-py2.7.egg\django\contrib\auth\middleware.py", line 22, in <lambda>
    request.user = SimpleLazyObject(lambda: get_user(request))
  File "C:\Python27\lib\site-packages\django-1.8.14-py2.7.egg\django\contrib\auth\middleware.py", line 10, in get_user
    request._cached_user = auth.get_user(request)
  File "C:\Python27\lib\site-packages\django-1.8.14-py2.7.egg\django\contrib\auth\__init__.py", line 167, in get_user
    user_id = _get_user_session_key(request)
  File "C:\Python27\lib\site-packages\django-1.8.14-py2.7.egg\django\contrib\auth\__init__.py", line 59, in _get_user_session_key
    return get_user_model()._meta.pk.to_python(request.session[SESSION_KEY])
  File "C:\Python27\lib\site-packages\django-1.8.14-py2.7.egg\django\contrib\sessions\backends\base.py", line 48, in __getitem__
    return self._session[key]
  File "C:\Python27\lib\site-packages\django-1.8.14-py2.7.egg\django\contrib\sessions\backends\base.py", line 181, in _get_session
    self._session_cache = self.load()
  File "C:\Python27\lib\site-packages\django-1.8.14-py2.7.egg\django\contrib\sessions\backends\db.py", line 21, in load
    expire_date__gt=timezone.now()
  File "C:\Python27\lib\site-packages\django-1.8.14-py2.7.egg\django\db\models\manager.py", line 127, in manager_method
    return getattr(self.get_queryset(), name)(*args, **kwargs)
  File "C:\Python27\lib\site-packages\django-1.8.14-py2.7.egg\django\db\models\query.py", line 328, in get
    num = len(clone)
  File "C:\Python27\lib\site-packages\django-1.8.14-py2.7.egg\django\db\models\query.py", line 144, in __len__
    self._fetch_all()
  File "C:\Python27\lib\site-packages\django-1.8.14-py2.7.egg\django\db\models\query.py", line 965, in _fetch_all
    self._result_cache = list(self.iterator())
  File "C:\Python27\lib\site-packages\django-1.8.14-py2.7.egg\django\db\models\query.py", line 238, in iterator
    results = compiler.execute_sql()
  File "C:\Python27\lib\site-packages\django-1.8.14-py2.7.egg\django\db\models\sql\compiler.py", line 838, in execute_sql
    cursor = self.connection.cursor()
  File "C:\Python27\lib\site-packages\django-1.8.14-py2.7.egg\django\db\backends\base\base.py", line 162, in cursor
    cursor = self.make_debug_cursor(self._cursor())
  File "C:\Python27\lib\site-packages\django-1.8.14-py2.7.egg\django\db\backends\base\base.py", line 135, in _cursor
    self.ensure_connection()
  File "C:\Python27\lib\site-packages\django-1.8.14-py2.7.egg\django\db\backends\base\base.py", line 130, in ensure_connection
    self.connect()
  File "C:\Python27\lib\site-packages\django-1.8.14-py2.7.egg\django\db\backends\base\base.py", line 121, in connect
    self.init_connection_state()
  File "C:\Python27\lib\site-packages\django-1.8.14-py2.7.egg\django\db\backends\mysql\base.py", line 287, in init_connection_state
    cursor.execute('SET SQL_AUTO_IS_NULL = 0')
  File "C:\Python27\lib\site-packages\django-1.8.14-py2.7.egg\django\db\backends\utils.py", line 79, in execute
    return super(CursorDebugWrapper, self).execute(sql, params)
  File "C:\Python27\lib\site-packages\django-1.8.14-py2.7.egg\django\db\backends\utils.py", line 64, in execute
    return self.cursor.execute(sql, params)
  File "C:\Python27\lib\site-packages\django-1.8.14-py2.7.egg\django\db\utils.py", line 98, in __exit__
    six.reraise(dj_exc_type, dj_exc_value, traceback)
  File "C:\Python27\lib\site-packages\django-1.8.14-py2.7.egg\django\db\backends\utils.py", line 62, in execute
    return self.cursor.execute(sql)
  File "C:\Python27\lib\site-packages\django-1.8.14-py2.7.egg\django\db\backends\mysql\base.py", line 124, in execute
    return self.cursor.execute(query, args)
  File "C:\Python27\lib\site-packages\MySQLdb\cursors.py", line 174, in execute
    self.errorhandler(self, exc, value)
  File "C:\Python27\lib\site-packages\MySQLdb\connections.py", line 36, in defaulterrorhandler
    raise errorclass, errorvalue
OperationalError: (2013, 'Lost connection to MySQL server during query')
[2016-10-14 13:47:41,250] [Thread-6:164] [django.request:170] [base:get_response] [WARNING]- Not Found: /favicon.ico
[2016-10-14 14:17:51,775] [Thread-40:5868] [django.request:256] [base:handle_uncaught_exception] [ERROR]- Internal Server Error: /cart/
Traceback (most recent call last):
  File "C:\Python27\lib\site-packages\django-1.8.14-py2.7.egg\django\core\handlers\base.py", line 132, in get_response
    response = wrapped_callback(request, *callback_args, **callback_kwargs)
  File "C:\Python27\lib\site-packages\django-1.8.14-py2.7.egg\django\contrib\auth\decorators.py", line 22, in _wrapped_view
    return view_func(request, *args, **kwargs)
  File "D:\PycharmProjects\fec\apps\ec\views.py", line 130, in get_cart_info
    context_dict = get_cart_detail(cust_id)
  File "D:\PycharmProjects\fec\apps\ec\views.py", line 118, in get_cart_detail
    status=1).values('so_id').annotate(total=Sum(F('qty') * F('price')))[0]['total']
  File "C:\Python27\lib\site-packages\django-1.8.14-py2.7.egg\django\db\models\query.py", line 201, in __getitem__
    return list(qs)[0]
IndexError: list index out of range
[2016-10-14 14:27:17,940] [Thread-2:3292] [django.request:256] [base:handle_uncaught_exception] [ERROR]- Internal Server Error: /cart/
Traceback (most recent call last):
  File "C:\Python27\lib\site-packages\django-1.8.14-py2.7.egg\django\core\handlers\base.py", line 132, in get_response
    response = wrapped_callback(request, *callback_args, **callback_kwargs)
  File "C:\Python27\lib\site-packages\django-1.8.14-py2.7.egg\django\contrib\auth\decorators.py", line 22, in _wrapped_view
    return view_func(request, *args, **kwargs)
  File "D:\PycharmProjects\fec\apps\ec\views.py", line 136, in get_cart_info
    context_dict = get_cart_detail(cust_id)
  File "D:\PycharmProjects\fec\apps\ec\views.py", line 124, in get_cart_detail
    status=1).values('so_id').annotate(total=Sum(F('qty') * F('price')))[0]['total']
  File "C:\Python27\lib\site-packages\django-1.8.14-py2.7.egg\django\db\models\query.py", line 201, in __getitem__
    return list(qs)[0]
IndexError: list index out of range
[2016-10-14 14:28:49,663] [Thread-6:5052] [django.request:256] [base:handle_uncaught_exception] [ERROR]- Internal Server Error: /cart/
Traceback (most recent call last):
  File "C:\Python27\lib\site-packages\django-1.8.14-py2.7.egg\django\core\handlers\base.py", line 132, in get_response
    response = wrapped_callback(request, *callback_args, **callback_kwargs)
  File "C:\Python27\lib\site-packages\django-1.8.14-py2.7.egg\django\contrib\auth\decorators.py", line 22, in _wrapped_view
    return view_func(request, *args, **kwargs)
  File "D:\PycharmProjects\fec\apps\ec\views.py", line 136, in get_cart_info
    return render(request,
  File "D:\PycharmProjects\fec\apps\ec\views.py", line 124, in get_cart_detail
    
  File "C:\Python27\lib\site-packages\django-1.8.14-py2.7.egg\django\db\models\query.py", line 201, in __getitem__
    return list(qs)[0]
IndexError: list index out of range
[2016-10-14 14:30:12,819] [Thread-9:4788] [django.request:256] [base:handle_uncaught_exception] [ERROR]- Internal Server Error: /cart/
Traceback (most recent call last):
  File "C:\Python27\lib\site-packages\django-1.8.14-py2.7.egg\django\core\handlers\base.py", line 132, in get_response
    response = wrapped_callback(request, *callback_args, **callback_kwargs)
  File "C:\Python27\lib\site-packages\django-1.8.14-py2.7.egg\django\contrib\auth\decorators.py", line 22, in _wrapped_view
    return view_func(request, *args, **kwargs)
  File "D:\PycharmProjects\fec\apps\ec\views.py", line 136, in get_cart_info
    cust_id = Cust.objects.get(user_id=User.objects.get(username=request.user.username).id).id
  File "D:\PycharmProjects\fec\apps\ec\views.py", line 124, in get_cart_detail
    total = Sol.objects.filter(cust_id=cust_id,
  File "C:\Python27\lib\site-packages\django-1.8.14-py2.7.egg\django\db\models\query.py", line 201, in __getitem__
    return list(qs)[0]
IndexError: list index out of range
[2016-10-14 14:31:32,819] [Thread-16:4132] [django.request:256] [base:handle_uncaught_exception] [ERROR]- Internal Server Error: /cart/
Traceback (most recent call last):
  File "C:\Python27\lib\site-packages\django-1.8.14-py2.7.egg\django\core\handlers\base.py", line 132, in get_response
    response = wrapped_callback(request, *callback_args, **callback_kwargs)
  File "C:\Python27\lib\site-packages\django-1.8.14-py2.7.egg\django\contrib\auth\decorators.py", line 22, in _wrapped_view
    return view_func(request, *args, **kwargs)
  File "D:\PycharmProjects\fec\apps\ec\views.py", line 136, in get_cart_info
    cust_id = Cust.objects.get(user_id=User.objects.get(username=request.user.username).id).id
  File "D:\PycharmProjects\fec\apps\ec\views.py", line 124, in get_cart_detail
    total = Sol.objects.filter(cust_id=cust_id,
  File "C:\Python27\lib\site-packages\django-1.8.14-py2.7.egg\django\db\models\query.py", line 201, in __getitem__
    return list(qs)[0]
IndexError: list index out of range
[2016-10-14 15:02:16,520] [Thread-9:1852] [django.request:170] [base:get_response] [WARNING]- Not Found: /favicon.ico
[2016-10-14 15:20:23,517] [Thread-3:3056] [django.request:170] [base:get_response] [WARNING]- Not Found: /favicon.ico
[2016-10-14 15:20:25,819] [Thread-8:3752] [django.request:256] [base:handle_uncaught_exception] [ERROR]- Internal Server Error: /goto_checkout/
Traceback (most recent call last):
  File "C:\Python27\lib\site-packages\django-1.8.14-py2.7.egg\django\core\handlers\base.py", line 132, in get_response
    response = wrapped_callback(request, *callback_args, **callback_kwargs)
  File "C:\Python27\lib\site-packages\django-1.8.14-py2.7.egg\django\contrib\auth\decorators.py", line 22, in _wrapped_view
    return view_func(request, *args, **kwargs)
  File "D:\PycharmProjects\fec\apps\ec\views.py", line 202, in goto_checkout
    context_dict)
  File "C:\Python27\lib\site-packages\django-1.8.14-py2.7.egg\django\shortcuts.py", line 67, in render
    template_name, context, request=request, using=using)
  File "C:\Python27\lib\site-packages\django-1.8.14-py2.7.egg\django\template\loader.py", line 99, in render_to_string
    return template.render(context, request)
  File "C:\Python27\lib\site-packages\django-1.8.14-py2.7.egg\django\template\backends\django.py", line 74, in render
    return self.template.render(context)
  File "C:\Python27\lib\site-packages\django-1.8.14-py2.7.egg\django\template\base.py", line 210, in render
    return self._render(context)
  File "C:\Python27\lib\site-packages\django-1.8.14-py2.7.egg\django\template\base.py", line 202, in _render
    return self.nodelist.render(context)
  File "C:\Python27\lib\site-packages\django-1.8.14-py2.7.egg\django\template\base.py", line 905, in render
    bit = self.render_node(node, context)
  File "C:\Python27\lib\site-packages\django-1.8.14-py2.7.egg\django\template\debug.py", line 79, in render_node
    return node.render(context)
  File "C:\Python27\lib\site-packages\django-1.8.14-py2.7.egg\django\template\loader_tags.py", line 135, in render
    return compiled_parent._render(context)
  File "C:\Python27\lib\site-packages\django-1.8.14-py2.7.egg\django\template\base.py", line 202, in _render
    return self.nodelist.render(context)
  File "C:\Python27\lib\site-packages\django-1.8.14-py2.7.egg\django\template\base.py", line 905, in render
    bit = self.render_node(node, context)
  File "C:\Python27\lib\site-packages\django-1.8.14-py2.7.egg\django\template\debug.py", line 79, in render_node
    return node.render(context)
  File "C:\Python27\lib\site-packages\django-1.8.14-py2.7.egg\django\template\loader_tags.py", line 135, in render
    return compiled_parent._render(context)
  File "C:\Python27\lib\site-packages\django-1.8.14-py2.7.egg\django\template\base.py", line 202, in _render
    return self.nodelist.render(context)
  File "C:\Python27\lib\site-packages\django-1.8.14-py2.7.egg\django\template\base.py", line 905, in render
    bit = self.render_node(node, context)
  File "C:\Python27\lib\site-packages\django-1.8.14-py2.7.egg\django\template\debug.py", line 79, in render_node
    return node.render(context)
  File "C:\Python27\lib\site-packages\django-1.8.14-py2.7.egg\django\template\loader_tags.py", line 65, in render
    result = block.nodelist.render(context)
  File "C:\Python27\lib\site-packages\django-1.8.14-py2.7.egg\django\template\base.py", line 905, in render
    bit = self.render_node(node, context)
  File "C:\Python27\lib\site-packages\django-1.8.14-py2.7.egg\django\template\debug.py", line 79, in render_node
    return node.render(context)
  File "C:\Python27\lib\site-packages\django-1.8.14-py2.7.egg\django\template\loader_tags.py", line 65, in render
    result = block.nodelist.render(context)
  File "C:\Python27\lib\site-packages\django-1.8.14-py2.7.egg\django\template\base.py", line 905, in render
    bit = self.render_node(node, context)
  File "C:\Python27\lib\site-packages\django-1.8.14-py2.7.egg\django\template\debug.py", line 79, in render_node
    return node.render(context)
  File "C:\Python27\lib\site-packages\django-1.8.14-py2.7.egg\django\template\defaulttags.py", line 507, in render
    six.reraise(*exc_info)
  File "C:\Python27\lib\site-packages\django-1.8.14-py2.7.egg\django\template\defaulttags.py", line 493, in render
    url = reverse(view_name, args=args, kwargs=kwargs, current_app=current_app)
  File "C:\Python27\lib\site-packages\django-1.8.14-py2.7.egg\django\core\urlresolvers.py", line 578, in reverse
    return force_text(iri_to_uri(resolver._reverse_with_prefix(view, prefix, *args, **kwargs)))
  File "C:\Python27\lib\site-packages\django-1.8.14-py2.7.egg\django\core\urlresolvers.py", line 495, in _reverse_with_prefix
    (lookup_view_s, args, kwargs, len(patterns), patterns))
NoReverseMatch: Reverse for 'checkout' with arguments '()' and keyword arguments '{}' not found. 0 pattern(s) tried: []
[2016-10-14 15:22:43,598] [Thread-22:2860] [django.request:256] [base:handle_uncaught_exception] [ERROR]- Internal Server Error: /goto_checkout/
Traceback (most recent call last):
  File "C:\Python27\lib\site-packages\django-1.8.14-py2.7.egg\django\core\handlers\base.py", line 132, in get_response
    response = wrapped_callback(request, *callback_args, **callback_kwargs)
  File "C:\Python27\lib\site-packages\django-1.8.14-py2.7.egg\django\contrib\auth\decorators.py", line 22, in _wrapped_view
    return view_func(request, *args, **kwargs)
  File "D:\PycharmProjects\fec\apps\ec\views.py", line 202, in goto_checkout
    context_dict)
  File "C:\Python27\lib\site-packages\django-1.8.14-py2.7.egg\django\shortcuts.py", line 67, in render
    template_name, context, request=request, using=using)
  File "C:\Python27\lib\site-packages\django-1.8.14-py2.7.egg\django\template\loader.py", line 99, in render_to_string
    return template.render(context, request)
  File "C:\Python27\lib\site-packages\django-1.8.14-py2.7.egg\django\template\backends\django.py", line 74, in render
    return self.template.render(context)
  File "C:\Python27\lib\site-packages\django-1.8.14-py2.7.egg\django\template\base.py", line 210, in render
    return self._render(context)
  File "C:\Python27\lib\site-packages\django-1.8.14-py2.7.egg\django\template\base.py", line 202, in _render
    return self.nodelist.render(context)
  File "C:\Python27\lib\site-packages\django-1.8.14-py2.7.egg\django\template\base.py", line 905, in render
    bit = self.render_node(node, context)
  File "C:\Python27\lib\site-packages\django-1.8.14-py2.7.egg\django\template\debug.py", line 79, in render_node
    return node.render(context)
  File "C:\Python27\lib\site-packages\django-1.8.14-py2.7.egg\django\template\loader_tags.py", line 135, in render
    return compiled_parent._render(context)
  File "C:\Python27\lib\site-packages\django-1.8.14-py2.7.egg\django\template\base.py", line 202, in _render
    return self.nodelist.render(context)
  File "C:\Python27\lib\site-packages\django-1.8.14-py2.7.egg\django\template\base.py", line 905, in render
    bit = self.render_node(node, context)
  File "C:\Python27\lib\site-packages\django-1.8.14-py2.7.egg\django\template\debug.py", line 79, in render_node
    return node.render(context)
  File "C:\Python27\lib\site-packages\django-1.8.14-py2.7.egg\django\template\loader_tags.py", line 135, in render
    return compiled_parent._render(context)
  File "C:\Python27\lib\site-packages\django-1.8.14-py2.7.egg\django\template\base.py", line 202, in _render
    return self.nodelist.render(context)
  File "C:\Python27\lib\site-packages\django-1.8.14-py2.7.egg\django\template\base.py", line 905, in render
    bit = self.render_node(node, context)
  File "C:\Python27\lib\site-packages\django-1.8.14-py2.7.egg\django\template\debug.py", line 79, in render_node
    return node.render(context)
  File "C:\Python27\lib\site-packages\django-1.8.14-py2.7.egg\django\template\loader_tags.py", line 65, in render
    result = block.nodelist.render(context)
  File "C:\Python27\lib\site-packages\django-1.8.14-py2.7.egg\django\template\base.py", line 905, in render
    bit = self.render_node(node, context)
  File "C:\Python27\lib\site-packages\django-1.8.14-py2.7.egg\django\template\debug.py", line 79, in render_node
    return node.render(context)
  File "C:\Python27\lib\site-packages\django-1.8.14-py2.7.egg\django\template\loader_tags.py", line 65, in render
    result = block.nodelist.render(context)
  File "C:\Python27\lib\site-packages\django-1.8.14-py2.7.egg\django\template\base.py", line 905, in render
    bit = self.render_node(node, context)
  File "C:\Python27\lib\site-packages\django-1.8.14-py2.7.egg\django\template\debug.py", line 79, in render_node
    return node.render(context)
  File "C:\Python27\lib\site-packages\django-1.8.14-py2.7.egg\django\template\defaulttags.py", line 507, in render
    six.reraise(*exc_info)
  File "C:\Python27\lib\site-packages\django-1.8.14-py2.7.egg\django\template\defaulttags.py", line 493, in render
    url = reverse(view_name, args=args, kwargs=kwargs, current_app=current_app)
  File "C:\Python27\lib\site-packages\django-1.8.14-py2.7.egg\django\core\urlresolvers.py", line 578, in reverse
    return force_text(iri_to_uri(resolver._reverse_with_prefix(view, prefix, *args, **kwargs)))
  File "C:\Python27\lib\site-packages\django-1.8.14-py2.7.egg\django\core\urlresolvers.py", line 495, in _reverse_with_prefix
    (lookup_view_s, args, kwargs, len(patterns), patterns))
NoReverseMatch: Reverse for 'checkout' with arguments '()' and keyword arguments '{}' not found. 0 pattern(s) tried: []
[2016-10-14 15:52:59,957] [Thread-2:672] [django.request:256] [base:handle_uncaught_exception] [ERROR]- Internal Server Error: /checkout/
Traceback (most recent call last):
  File "C:\Python27\lib\site-packages\django-1.8.14-py2.7.egg\django\core\handlers\base.py", line 132, in get_response
    response = wrapped_callback(request, *callback_args, **callback_kwargs)
  File "C:\Python27\lib\site-packages\django-1.8.14-py2.7.egg\django\contrib\auth\decorators.py", line 21, in _wrapped_view
    if test_func(request.user):
  File "C:\Python27\lib\site-packages\django-1.8.14-py2.7.egg\django\contrib\auth\decorators.py", line 45, in <lambda>
    lambda u: u.is_authenticated(),
  File "C:\Python27\lib\site-packages\django-1.8.14-py2.7.egg\django\utils\functional.py", line 225, in inner
    self._setup()
  File "C:\Python27\lib\site-packages\django-1.8.14-py2.7.egg\django\utils\functional.py", line 376, in _setup
    self._wrapped = self._setupfunc()
  File "C:\Python27\lib\site-packages\django-1.8.14-py2.7.egg\django\contrib\auth\middleware.py", line 22, in <lambda>
    request.user = SimpleLazyObject(lambda: get_user(request))
  File "C:\Python27\lib\site-packages\django-1.8.14-py2.7.egg\django\contrib\auth\middleware.py", line 10, in get_user
    request._cached_user = auth.get_user(request)
  File "C:\Python27\lib\site-packages\django-1.8.14-py2.7.egg\django\contrib\auth\__init__.py", line 167, in get_user
    user_id = _get_user_session_key(request)
  File "C:\Python27\lib\site-packages\django-1.8.14-py2.7.egg\django\contrib\auth\__init__.py", line 59, in _get_user_session_key
    return get_user_model()._meta.pk.to_python(request.session[SESSION_KEY])
  File "C:\Python27\lib\site-packages\django-1.8.14-py2.7.egg\django\contrib\sessions\backends\base.py", line 48, in __getitem__
    return self._session[key]
  File "C:\Python27\lib\site-packages\django-1.8.14-py2.7.egg\django\contrib\sessions\backends\base.py", line 181, in _get_session
    self._session_cache = self.load()
  File "C:\Python27\lib\site-packages\django-1.8.14-py2.7.egg\django\contrib\sessions\backends\db.py", line 21, in load
    expire_date__gt=timezone.now()
  File "C:\Python27\lib\site-packages\django-1.8.14-py2.7.egg\django\db\models\manager.py", line 127, in manager_method
    return getattr(self.get_queryset(), name)(*args, **kwargs)
  File "C:\Python27\lib\site-packages\django-1.8.14-py2.7.egg\django\db\models\query.py", line 328, in get
    num = len(clone)
  File "C:\Python27\lib\site-packages\django-1.8.14-py2.7.egg\django\db\models\query.py", line 144, in __len__
    self._fetch_all()
  File "C:\Python27\lib\site-packages\django-1.8.14-py2.7.egg\django\db\models\query.py", line 965, in _fetch_all
    self._result_cache = list(self.iterator())
  File "C:\Python27\lib\site-packages\django-1.8.14-py2.7.egg\django\db\models\query.py", line 238, in iterator
    results = compiler.execute_sql()
  File "C:\Python27\lib\site-packages\django-1.8.14-py2.7.egg\django\db\models\sql\compiler.py", line 838, in execute_sql
    cursor = self.connection.cursor()
  File "C:\Python27\lib\site-packages\django-1.8.14-py2.7.egg\django\db\backends\base\base.py", line 162, in cursor
    cursor = self.make_debug_cursor(self._cursor())
  File "C:\Python27\lib\site-packages\django-1.8.14-py2.7.egg\django\db\backends\base\base.py", line 135, in _cursor
    self.ensure_connection()
  File "C:\Python27\lib\site-packages\django-1.8.14-py2.7.egg\django\db\backends\base\base.py", line 130, in ensure_connection
    self.connect()
  File "C:\Python27\lib\site-packages\django-1.8.14-py2.7.egg\django\db\utils.py", line 98, in __exit__
    six.reraise(dj_exc_type, dj_exc_value, traceback)
  File "C:\Python27\lib\site-packages\django-1.8.14-py2.7.egg\django\db\backends\base\base.py", line 130, in ensure_connection
    self.connect()
  File "C:\Python27\lib\site-packages\django-1.8.14-py2.7.egg\django\db\backends\base\base.py", line 119, in connect
    self.connection = self.get_new_connection(conn_params)
  File "C:\Python27\lib\site-packages\django-1.8.14-py2.7.egg\django\db\backends\mysql\base.py", line 276, in get_new_connection
    conn = Database.connect(**conn_params)
  File "C:\Python27\lib\site-packages\MySQLdb\__init__.py", line 81, in Connect
    return Connection(*args, **kwargs)
  File "C:\Python27\lib\site-packages\MySQLdb\connections.py", line 187, in __init__
    super(Connection, self).__init__(*args, **kwargs2)
OperationalError: (2003, "Can't connect to MySQL server on '115.29.239.5' (10060)")
[2016-10-14 15:54:20,907] [Thread-4:2748] [django.request:256] [base:handle_uncaught_exception] [ERROR]- Internal Server Error: /checkout/
Traceback (most recent call last):
  File "C:\Python27\lib\site-packages\django-1.8.14-py2.7.egg\django\core\handlers\base.py", line 132, in get_response
    response = wrapped_callback(request, *callback_args, **callback_kwargs)
  File "C:\Python27\lib\site-packages\django-1.8.14-py2.7.egg\django\contrib\auth\decorators.py", line 21, in _wrapped_view
    if test_func(request.user):
  File "C:\Python27\lib\site-packages\django-1.8.14-py2.7.egg\django\contrib\auth\decorators.py", line 45, in <lambda>
    lambda u: u.is_authenticated(),
  File "C:\Python27\lib\site-packages\django-1.8.14-py2.7.egg\django\utils\functional.py", line 225, in inner
    self._setup()
  File "C:\Python27\lib\site-packages\django-1.8.14-py2.7.egg\django\utils\functional.py", line 376, in _setup
    self._wrapped = self._setupfunc()
  File "C:\Python27\lib\site-packages\django-1.8.14-py2.7.egg\django\contrib\auth\middleware.py", line 22, in <lambda>
    request.user = SimpleLazyObject(lambda: get_user(request))
  File "C:\Python27\lib\site-packages\django-1.8.14-py2.7.egg\django\contrib\auth\middleware.py", line 10, in get_user
    request._cached_user = auth.get_user(request)
  File "C:\Python27\lib\site-packages\django-1.8.14-py2.7.egg\django\contrib\auth\__init__.py", line 167, in get_user
    user_id = _get_user_session_key(request)
  File "C:\Python27\lib\site-packages\django-1.8.14-py2.7.egg\django\contrib\auth\__init__.py", line 59, in _get_user_session_key
    return get_user_model()._meta.pk.to_python(request.session[SESSION_KEY])
  File "C:\Python27\lib\site-packages\django-1.8.14-py2.7.egg\django\contrib\sessions\backends\base.py", line 48, in __getitem__
    return self._session[key]
  File "C:\Python27\lib\site-packages\django-1.8.14-py2.7.egg\django\contrib\sessions\backends\base.py", line 181, in _get_session
    self._session_cache = self.load()
  File "C:\Python27\lib\site-packages\django-1.8.14-py2.7.egg\django\contrib\sessions\backends\db.py", line 21, in load
    expire_date__gt=timezone.now()
  File "C:\Python27\lib\site-packages\django-1.8.14-py2.7.egg\django\db\models\manager.py", line 127, in manager_method
    return getattr(self.get_queryset(), name)(*args, **kwargs)
  File "C:\Python27\lib\site-packages\django-1.8.14-py2.7.egg\django\db\models\query.py", line 328, in get
    num = len(clone)
  File "C:\Python27\lib\site-packages\django-1.8.14-py2.7.egg\django\db\models\query.py", line 144, in __len__
    self._fetch_all()
  File "C:\Python27\lib\site-packages\django-1.8.14-py2.7.egg\django\db\models\query.py", line 965, in _fetch_all
    self._result_cache = list(self.iterator())
  File "C:\Python27\lib\site-packages\django-1.8.14-py2.7.egg\django\db\models\query.py", line 238, in iterator
    results = compiler.execute_sql()
  File "C:\Python27\lib\site-packages\django-1.8.14-py2.7.egg\django\db\models\sql\compiler.py", line 840, in execute_sql
    cursor.execute(sql, params)
  File "C:\Python27\lib\site-packages\django-1.8.14-py2.7.egg\django\db\backends\utils.py", line 79, in execute
    return super(CursorDebugWrapper, self).execute(sql, params)
  File "C:\Python27\lib\site-packages\django-1.8.14-py2.7.egg\django\db\backends\utils.py", line 64, in execute
    return self.cursor.execute(sql, params)
  File "C:\Python27\lib\site-packages\django-1.8.14-py2.7.egg\django\db\utils.py", line 98, in __exit__
    six.reraise(dj_exc_type, dj_exc_value, traceback)
  File "C:\Python27\lib\site-packages\django-1.8.14-py2.7.egg\django\db\backends\utils.py", line 64, in execute
    return self.cursor.execute(sql, params)
  File "C:\Python27\lib\site-packages\django-1.8.14-py2.7.egg\django\db\backends\mysql\base.py", line 124, in execute
    return self.cursor.execute(query, args)
  File "C:\Python27\lib\site-packages\MySQLdb\cursors.py", line 174, in execute
    self.errorhandler(self, exc, value)
  File "C:\Python27\lib\site-packages\MySQLdb\connections.py", line 36, in defaulterrorhandler
    raise errorclass, errorvalue
OperationalError: (2013, 'Lost connection to MySQL server during query')
[2017-01-04 19:18:06,802] [Thread-10:3100] [django.request:170] [base:get_response] [WARNING]- Not Found: /favicon.ico
[2017-01-04 19:20:38,845] [Thread-30:2208] [django.request:256] [base:handle_uncaught_exception] [ERROR]- Internal Server Error: /checkout_confirm/
Traceback (most recent call last):
  File "C:\Python27\lib\site-packages\django-1.8.14-py2.7.egg\django\core\handlers\base.py", line 132, in get_response
    response = wrapped_callback(request, *callback_args, **callback_kwargs)
  File "C:\Python27\lib\site-packages\django-1.8.14-py2.7.egg\django\contrib\auth\decorators.py", line 22, in _wrapped_view
    return view_func(request, *args, **kwargs)
  File "D:\PycharmProjects\fec\apps\ec\views.py", line 219, in checkout_confirm
    so = So.objects.filter(cust_id=cust.id, status=1)[0]
  File "C:\Python27\lib\site-packages\django-1.8.14-py2.7.egg\django\db\models\query.py", line 201, in __getitem__
    return list(qs)[0]
IndexError: list index out of range
[2017-01-04 19:31:43,986] [Thread-11:2072] [django.request:256] [base:handle_uncaught_exception] [ERROR]- Internal Server Error: /checkout_confirm/
Traceback (most recent call last):
  File "C:\Python27\lib\site-packages\django-1.8.14-py2.7.egg\django\core\handlers\base.py", line 132, in get_response
    response = wrapped_callback(request, *callback_args, **callback_kwargs)
  File "C:\Python27\lib\site-packages\django-1.8.14-py2.7.egg\django\contrib\auth\decorators.py", line 22, in _wrapped_view
    return view_func(request, *args, **kwargs)
  File "D:\PycharmProjects\fec\apps\ec\views.py", line 219, in checkout_confirm
    so = So.objects.filter(cust_id=cust.id, status=1)[0]
  File "C:\Python27\lib\site-packages\django-1.8.14-py2.7.egg\django\db\models\query.py", line 201, in __getitem__
    return list(qs)[0]
IndexError: list index out of range
[2017-01-04 19:31:54,944] [Thread-15:2380] [django.request:256] [base:handle_uncaught_exception] [ERROR]- Internal Server Error: /checkout_confirm/
Traceback (most recent call last):
  File "C:\Python27\lib\site-packages\django-1.8.14-py2.7.egg\django\core\handlers\base.py", line 132, in get_response
    response = wrapped_callback(request, *callback_args, **callback_kwargs)
  File "C:\Python27\lib\site-packages\django-1.8.14-py2.7.egg\django\contrib\auth\decorators.py", line 22, in _wrapped_view
    return view_func(request, *args, **kwargs)
  File "D:\PycharmProjects\fec\apps\ec\views.py", line 219, in checkout_confirm
    so = So.objects.filter(cust_id=cust.id, status=1)[0]
  File "C:\Python27\lib\site-packages\django-1.8.14-py2.7.egg\django\db\models\query.py", line 201, in __getitem__
    return list(qs)[0]
IndexError: list index out of range
[2017-01-04 19:47:34,354] [Thread-8:604] [django.request:170] [base:get_response] [WARNING]- Not Found: /favicon.ico
[2017-01-05 11:35:29,782] [Thread-10:2984] [django.request:170] [base:get_response] [WARNING]- Not Found: /favicon.ico
[2017-01-05 13:50:20,398] [Thread-6:2140] [django.request:170] [base:get_response] [WARNING]- Not Found: /favicon.ico
[2017-01-05 14:52:42,431] [Thread-3:3848] [django.request:256] [base:handle_uncaught_exception] [ERROR]- Internal Server Error: /ec/order_list/
Traceback (most recent call last):
  File "C:\Python27\lib\site-packages\django-1.8.14-py2.7.egg\django\core\handlers\base.py", line 132, in get_response
    response = wrapped_callback(request, *callback_args, **callback_kwargs)
  File "C:\Python27\lib\site-packages\django-1.8.14-py2.7.egg\django\contrib\auth\decorators.py", line 21, in _wrapped_view
    if test_func(request.user):
  File "C:\Python27\lib\site-packages\django-1.8.14-py2.7.egg\django\contrib\auth\decorators.py", line 45, in <lambda>
    lambda u: u.is_authenticated(),
  File "C:\Python27\lib\site-packages\django-1.8.14-py2.7.egg\django\utils\functional.py", line 225, in inner
    self._setup()
  File "C:\Python27\lib\site-packages\django-1.8.14-py2.7.egg\django\utils\functional.py", line 376, in _setup
    self._wrapped = self._setupfunc()
  File "C:\Python27\lib\site-packages\django-1.8.14-py2.7.egg\django\contrib\auth\middleware.py", line 22, in <lambda>
    request.user = SimpleLazyObject(lambda: get_user(request))
  File "C:\Python27\lib\site-packages\django-1.8.14-py2.7.egg\django\contrib\auth\middleware.py", line 10, in get_user
    request._cached_user = auth.get_user(request)
  File "C:\Python27\lib\site-packages\django-1.8.14-py2.7.egg\django\contrib\auth\__init__.py", line 167, in get_user
    user_id = _get_user_session_key(request)
  File "C:\Python27\lib\site-packages\django-1.8.14-py2.7.egg\django\contrib\auth\__init__.py", line 59, in _get_user_session_key
    return get_user_model()._meta.pk.to_python(request.session[SESSION_KEY])
  File "C:\Python27\lib\site-packages\django-1.8.14-py2.7.egg\django\contrib\sessions\backends\base.py", line 48, in __getitem__
    return self._session[key]
  File "C:\Python27\lib\site-packages\django-1.8.14-py2.7.egg\django\contrib\sessions\backends\base.py", line 181, in _get_session
    self._session_cache = self.load()
  File "C:\Python27\lib\site-packages\django-1.8.14-py2.7.egg\django\contrib\sessions\backends\db.py", line 21, in load
    expire_date__gt=timezone.now()
  File "C:\Python27\lib\site-packages\django-1.8.14-py2.7.egg\django\db\models\manager.py", line 127, in manager_method
    return getattr(self.get_queryset(), name)(*args, **kwargs)
  File "C:\Python27\lib\site-packages\django-1.8.14-py2.7.egg\django\db\models\query.py", line 328, in get
    num = len(clone)
  File "C:\Python27\lib\site-packages\django-1.8.14-py2.7.egg\django\db\models\query.py", line 144, in __len__
    self._fetch_all()
  File "C:\Python27\lib\site-packages\django-1.8.14-py2.7.egg\django\db\models\query.py", line 965, in _fetch_all
    self._result_cache = list(self.iterator())
  File "C:\Python27\lib\site-packages\django-1.8.14-py2.7.egg\django\db\models\query.py", line 238, in iterator
    results = compiler.execute_sql()
  File "C:\Python27\lib\site-packages\django-1.8.14-py2.7.egg\django\db\models\sql\compiler.py", line 829, in execute_sql
    sql, params = self.as_sql()
  File "C:\Python27\lib\site-packages\django-1.8.14-py2.7.egg\django\db\models\sql\compiler.py", line 387, in as_sql
    where, w_params = self.compile(self.query.where)
  File "C:\Python27\lib\site-packages\django-1.8.14-py2.7.egg\django\db\models\sql\compiler.py", line 357, in compile
    sql, params = node.as_sql(self, self.connection)
  File "C:\Python27\lib\site-packages\django-1.8.14-py2.7.egg\django\db\models\sql\where.py", line 104, in as_sql
    sql, params = compiler.compile(child)
  File "C:\Python27\lib\site-packages\django-1.8.14-py2.7.egg\django\db\models\sql\compiler.py", line 357, in compile
    sql, params = node.as_sql(self, self.connection)
  File "C:\Python27\lib\site-packages\django-1.8.14-py2.7.egg\django\db\models\lookups.py", line 218, in as_sql
    lhs_sql, params = self.process_lhs(compiler, connection)
  File "C:\Python27\lib\site-packages\django-1.8.14-py2.7.egg\django\db\models\lookups.py", line 211, in process_lhs
    db_type = self.lhs.output_field.db_type(connection=connection)
  File "C:\Python27\lib\site-packages\django-1.8.14-py2.7.egg\django\db\models\fields\__init__.py", line 614, in db_type
    return connection.data_types[self.get_internal_type()] % data
  File "C:\Python27\lib\site-packages\django-1.8.14-py2.7.egg\django\utils\functional.py", line 59, in __get__
    res = instance.__dict__[self.name] = self.func(instance)
  File "C:\Python27\lib\site-packages\django-1.8.14-py2.7.egg\django\db\backends\mysql\base.py", line 196, in data_types
    if self.features.supports_microsecond_precision:
  File "C:\Python27\lib\site-packages\django-1.8.14-py2.7.egg\django\utils\functional.py", line 59, in __get__
    res = instance.__dict__[self.name] = self.func(instance)
  File "C:\Python27\lib\site-packages\django-1.8.14-py2.7.egg\django\db\backends\mysql\features.py", line 52, in supports_microsecond_precision
    return self.connection.mysql_version >= (5, 6, 4) and Database.version_info >= (1, 2, 5)
  File "C:\Python27\lib\site-packages\django-1.8.14-py2.7.egg\django\utils\functional.py", line 59, in __get__
    res = instance.__dict__[self.name] = self.func(instance)
  File "C:\Python27\lib\site-packages\django-1.8.14-py2.7.egg\django\db\backends\mysql\base.py", line 371, in mysql_version
    with self.temporary_connection():
  File "C:\Python27\lib\contextlib.py", line 17, in __enter__
    return self.gen.next()
  File "C:\Python27\lib\site-packages\django-1.8.14-py2.7.egg\django\db\backends\base\base.py", line 462, in temporary_connection
    cursor = self.cursor()
  File "C:\Python27\lib\site-packages\django-1.8.14-py2.7.egg\django\db\backends\base\base.py", line 162, in cursor
    cursor = self.make_debug_cursor(self._cursor())
  File "C:\Python27\lib\site-packages\django-1.8.14-py2.7.egg\django\db\backends\base\base.py", line 135, in _cursor
    self.ensure_connection()
  File "C:\Python27\lib\site-packages\django-1.8.14-py2.7.egg\django\db\backends\base\base.py", line 130, in ensure_connection
    self.connect()
  File "C:\Python27\lib\site-packages\django-1.8.14-py2.7.egg\django\db\utils.py", line 98, in __exit__
    six.reraise(dj_exc_type, dj_exc_value, traceback)
  File "C:\Python27\lib\site-packages\django-1.8.14-py2.7.egg\django\db\backends\base\base.py", line 130, in ensure_connection
    self.connect()
  File "C:\Python27\lib\site-packages\django-1.8.14-py2.7.egg\django\db\backends\base\base.py", line 119, in connect
    self.connection = self.get_new_connection(conn_params)
  File "C:\Python27\lib\site-packages\django-1.8.14-py2.7.egg\django\db\backends\mysql\base.py", line 276, in get_new_connection
    conn = Database.connect(**conn_params)
  File "C:\Python27\lib\site-packages\MySQLdb\__init__.py", line 81, in Connect
    return Connection(*args, **kwargs)
  File "C:\Python27\lib\site-packages\MySQLdb\connections.py", line 187, in __init__
    super(Connection, self).__init__(*args, **kwargs2)
OperationalError: (2003, "Can't connect to MySQL server on '115.29.239.5' (10060)")
[2017-01-05 14:59:33,941] [Thread-16:2836] [django.request:170] [base:get_response] [WARNING]- Not Found: /order_list/
[2017-01-05 14:59:35,519] [Thread-18:2272] [django.request:170] [base:get_response] [WARNING]- Not Found: /order_list/
[2017-01-05 14:59:37,301] [Thread-17:1376] [django.request:170] [base:get_response] [WARNING]- Not Found: /order_list/
[2017-01-05 14:59:50,772] [Thread-19:3112] [django.request:170] [base:get_response] [WARNING]- Not Found: /order_list/
[2017-01-05 14:59:52,049] [Thread-20:3340] [django.request:170] [base:get_response] [WARNING]- Not Found: /order_list/
[2017-01-05 14:59:52,690] [Thread-21:3524] [django.request:170] [base:get_response] [WARNING]- Not Found: /order_list/
[2017-01-05 15:03:52,892] [Thread-7:3328] [django.request:256] [base:handle_uncaught_exception] [ERROR]- Internal Server Error: /order_list/
Traceback (most recent call last):
  File "C:\Python27\lib\site-packages\django-1.8.14-py2.7.egg\django\core\handlers\base.py", line 132, in get_response
    response = wrapped_callback(request, *callback_args, **callback_kwargs)
  File "C:\Python27\lib\site-packages\django-1.8.14-py2.7.egg\django\contrib\auth\decorators.py", line 22, in _wrapped_view
    return view_func(request, *args, **kwargs)
  File "D:\PycharmProjects\fec\apps\ec\views.py", line 256, in get_order_list
    context_dict)
  File "C:\Python27\lib\site-packages\django-1.8.14-py2.7.egg\django\shortcuts.py", line 67, in render
    template_name, context, request=request, using=using)
  File "C:\Python27\lib\site-packages\django-1.8.14-py2.7.egg\django\template\loader.py", line 99, in render_to_string
    return template.render(context, request)
  File "C:\Python27\lib\site-packages\django-1.8.14-py2.7.egg\django\template\backends\django.py", line 74, in render
    return self.template.render(context)
  File "C:\Python27\lib\site-packages\django-1.8.14-py2.7.egg\django\template\base.py", line 210, in render
    return self._render(context)
  File "C:\Python27\lib\site-packages\django-1.8.14-py2.7.egg\django\template\base.py", line 202, in _render
    return self.nodelist.render(context)
  File "C:\Python27\lib\site-packages\django-1.8.14-py2.7.egg\django\template\base.py", line 905, in render
    bit = self.render_node(node, context)
  File "C:\Python27\lib\site-packages\django-1.8.14-py2.7.egg\django\template\debug.py", line 79, in render_node
    return node.render(context)
  File "C:\Python27\lib\site-packages\django-1.8.14-py2.7.egg\django\template\loader_tags.py", line 135, in render
    return compiled_parent._render(context)
  File "C:\Python27\lib\site-packages\django-1.8.14-py2.7.egg\django\template\base.py", line 202, in _render
    return self.nodelist.render(context)
  File "C:\Python27\lib\site-packages\django-1.8.14-py2.7.egg\django\template\base.py", line 905, in render
    bit = self.render_node(node, context)
  File "C:\Python27\lib\site-packages\django-1.8.14-py2.7.egg\django\template\debug.py", line 79, in render_node
    return node.render(context)
  File "C:\Python27\lib\site-packages\django-1.8.14-py2.7.egg\django\template\loader_tags.py", line 135, in render
    return compiled_parent._render(context)
  File "C:\Python27\lib\site-packages\django-1.8.14-py2.7.egg\django\template\base.py", line 202, in _render
    return self.nodelist.render(context)
  File "C:\Python27\lib\site-packages\django-1.8.14-py2.7.egg\django\template\base.py", line 905, in render
    bit = self.render_node(node, context)
  File "C:\Python27\lib\site-packages\django-1.8.14-py2.7.egg\django\template\debug.py", line 79, in render_node
    return node.render(context)
  File "C:\Python27\lib\site-packages\django-1.8.14-py2.7.egg\django\template\loader_tags.py", line 65, in render
    result = block.nodelist.render(context)
  File "C:\Python27\lib\site-packages\django-1.8.14-py2.7.egg\django\template\base.py", line 905, in render
    bit = self.render_node(node, context)
  File "C:\Python27\lib\site-packages\django-1.8.14-py2.7.egg\django\template\debug.py", line 79, in render_node
    return node.render(context)
  File "C:\Python27\lib\site-packages\django-1.8.14-py2.7.egg\django\template\loader_tags.py", line 65, in render
    result = block.nodelist.render(context)
  File "C:\Python27\lib\site-packages\django-1.8.14-py2.7.egg\django\template\base.py", line 905, in render
    bit = self.render_node(node, context)
  File "C:\Python27\lib\site-packages\django-1.8.14-py2.7.egg\django\template\debug.py", line 79, in render_node
    return node.render(context)
  File "C:\Python27\lib\site-packages\django-1.8.14-py2.7.egg\django\template\defaulttags.py", line 217, in render
    nodelist.append(node.render(context))
  File "C:\Python27\lib\site-packages\django-1.8.14-py2.7.egg\django\template\defaulttags.py", line 507, in render
    six.reraise(*exc_info)
  File "C:\Python27\lib\site-packages\django-1.8.14-py2.7.egg\django\template\defaulttags.py", line 493, in render
    url = reverse(view_name, args=args, kwargs=kwargs, current_app=current_app)
  File "C:\Python27\lib\site-packages\django-1.8.14-py2.7.egg\django\core\urlresolvers.py", line 578, in reverse
    return force_text(iri_to_uri(resolver._reverse_with_prefix(view, prefix, *args, **kwargs)))
  File "C:\Python27\lib\site-packages\django-1.8.14-py2.7.egg\django\core\urlresolvers.py", line 495, in _reverse_with_prefix
    (lookup_view_s, args, kwargs, len(patterns), patterns))
NoReverseMatch: Reverse for 'order_detail' with arguments '()' and keyword arguments '{u'id': 1L}' not found. 1 pattern(s) tried: ['order_detail/(?P<order_id>\\d+)/$']
[2017-01-05 15:05:09,319] [Thread-2:164] [django.request:256] [base:handle_uncaught_exception] [ERROR]- Internal Server Error: /order_list/
Traceback (most recent call last):
  File "C:\Python27\lib\site-packages\django-1.8.14-py2.7.egg\django\core\handlers\base.py", line 132, in get_response
    response = wrapped_callback(request, *callback_args, **callback_kwargs)
  File "C:\Python27\lib\site-packages\django-1.8.14-py2.7.egg\django\contrib\auth\decorators.py", line 22, in _wrapped_view
    return view_func(request, *args, **kwargs)
  File "D:\PycharmProjects\fec\apps\ec\views.py", line 256, in get_order_list
    context_dict)
  File "C:\Python27\lib\site-packages\django-1.8.14-py2.7.egg\django\shortcuts.py", line 67, in render
    template_name, context, request=request, using=using)
  File "C:\Python27\lib\site-packages\django-1.8.14-py2.7.egg\django\template\loader.py", line 99, in render_to_string
    return template.render(context, request)
  File "C:\Python27\lib\site-packages\django-1.8.14-py2.7.egg\django\template\backends\django.py", line 74, in render
    return self.template.render(context)
  File "C:\Python27\lib\site-packages\django-1.8.14-py2.7.egg\django\template\base.py", line 210, in render
    return self._render(context)
  File "C:\Python27\lib\site-packages\django-1.8.14-py2.7.egg\django\template\base.py", line 202, in _render
    return self.nodelist.render(context)
  File "C:\Python27\lib\site-packages\django-1.8.14-py2.7.egg\django\template\base.py", line 905, in render
    bit = self.render_node(node, context)
  File "C:\Python27\lib\site-packages\django-1.8.14-py2.7.egg\django\template\debug.py", line 79, in render_node
    return node.render(context)
  File "C:\Python27\lib\site-packages\django-1.8.14-py2.7.egg\django\template\loader_tags.py", line 135, in render
    return compiled_parent._render(context)
  File "C:\Python27\lib\site-packages\django-1.8.14-py2.7.egg\django\template\base.py", line 202, in _render
    return self.nodelist.render(context)
  File "C:\Python27\lib\site-packages\django-1.8.14-py2.7.egg\django\template\base.py", line 905, in render
    bit = self.render_node(node, context)
  File "C:\Python27\lib\site-packages\django-1.8.14-py2.7.egg\django\template\debug.py", line 79, in render_node
    return node.render(context)
  File "C:\Python27\lib\site-packages\django-1.8.14-py2.7.egg\django\template\loader_tags.py", line 135, in render
    return compiled_parent._render(context)
  File "C:\Python27\lib\site-packages\django-1.8.14-py2.7.egg\django\template\base.py", line 202, in _render
    return self.nodelist.render(context)
  File "C:\Python27\lib\site-packages\django-1.8.14-py2.7.egg\django\template\base.py", line 905, in render
    bit = self.render_node(node, context)
  File "C:\Python27\lib\site-packages\django-1.8.14-py2.7.egg\django\template\debug.py", line 79, in render_node
    return node.render(context)
  File "C:\Python27\lib\site-packages\django-1.8.14-py2.7.egg\django\template\loader_tags.py", line 65, in render
    result = block.nodelist.render(context)
  File "C:\Python27\lib\site-packages\django-1.8.14-py2.7.egg\django\template\base.py", line 905, in render
    bit = self.render_node(node, context)
  File "C:\Python27\lib\site-packages\django-1.8.14-py2.7.egg\django\template\debug.py", line 79, in render_node
    return node.render(context)
  File "C:\Python27\lib\site-packages\django-1.8.14-py2.7.egg\django\template\loader_tags.py", line 65, in render
    result = block.nodelist.render(context)
  File "C:\Python27\lib\site-packages\django-1.8.14-py2.7.egg\django\template\base.py", line 905, in render
    bit = self.render_node(node, context)
  File "C:\Python27\lib\site-packages\django-1.8.14-py2.7.egg\django\template\debug.py", line 79, in render_node
    return node.render(context)
  File "C:\Python27\lib\site-packages\django-1.8.14-py2.7.egg\django\template\defaulttags.py", line 217, in render
    nodelist.append(node.render(context))
  File "C:\Python27\lib\site-packages\django-1.8.14-py2.7.egg\django\template\defaulttags.py", line 507, in render
    six.reraise(*exc_info)
  File "C:\Python27\lib\site-packages\django-1.8.14-py2.7.egg\django\template\defaulttags.py", line 493, in render
    url = reverse(view_name, args=args, kwargs=kwargs, current_app=current_app)
  File "C:\Python27\lib\site-packages\django-1.8.14-py2.7.egg\django\core\urlresolvers.py", line 578, in reverse
    return force_text(iri_to_uri(resolver._reverse_with_prefix(view, prefix, *args, **kwargs)))
  File "C:\Python27\lib\site-packages\django-1.8.14-py2.7.egg\django\core\urlresolvers.py", line 495, in _reverse_with_prefix
    (lookup_view_s, args, kwargs, len(patterns), patterns))
NoReverseMatch: Reverse for 'order_detail' with arguments '()' and keyword arguments '{u'so_id': 1L}' not found. 1 pattern(s) tried: ['order_detail/(?P<order_id>\\d+)/$']
[2017-01-10 15:04:41,105] [Thread-9:1796] [django.request:170] [base:get_response] [WARNING]- Not Found: /favicon.ico
[2017-01-10 16:09:51,803] [Thread-2:2688] [django.request:98] [csrf:_reject] [WARNING]- Forbidden (CSRF token missing or incorrect.): /accounts/login/
[2017-01-10 16:09:55,058] [Thread-3:1896] [django.request:98] [csrf:_reject] [WARNING]- Forbidden (CSRF token missing or incorrect.): /accounts/login/
[2017-01-11 09:22:47,499] [Thread-7:2848] [django.request:170] [base:get_response] [WARNING]- Not Found: /favicon.ico
[2017-01-11 09:29:52,243] [Thread-22:900] [django.request:256] [base:handle_uncaught_exception] [ERROR]- Internal Server Error: /ec/add_prod/
Traceback (most recent call last):
  File "C:\Python27\lib\site-packages\django-1.8.14-py2.7.egg\django\core\handlers\base.py", line 132, in get_response
    response = wrapped_callback(request, *callback_args, **callback_kwargs)
  File "C:\Python27\lib\site-packages\django-1.8.14-py2.7.egg\django\contrib\auth\decorators.py", line 22, in _wrapped_view
    return view_func(request, *args, **kwargs)
  File "D:\PycharmProjects\fec\apps\ec\views.py", line 163, in add_prod
    context_dict = get_cart_detail(cust_id)
  File "C:\Python27\lib\site-packages\django-1.8.14-py2.7.egg\django\contrib\auth\decorators.py", line 21, in _wrapped_view
    if test_func(request.user):
AttributeError: 'long' object has no attribute 'user'
[2017-01-11 09:40:05,391] [Thread-75:1332] [django.request:170] [base:get_response] [WARNING]- Not Found: /favicon.ico
[2017-01-11 09:40:07,778] [Thread-76:2636] [django.request:256] [base:handle_uncaught_exception] [ERROR]- Internal Server Error: /ec/add_prod/
Traceback (most recent call last):
  File "C:\Python27\lib\site-packages\django-1.8.14-py2.7.egg\django\core\handlers\base.py", line 132, in get_response
    response = wrapped_callback(request, *callback_args, **callback_kwargs)
  File "C:\Python27\lib\site-packages\django-1.8.14-py2.7.egg\django\contrib\auth\decorators.py", line 22, in _wrapped_view
    return view_func(request, *args, **kwargs)
  File "D:\PycharmProjects\fec\apps\ec\views.py", line 163, in add_prod
    context_dict = get_cart_detail(cust_id)
  File "C:\Python27\lib\site-packages\django-1.8.14-py2.7.egg\django\contrib\auth\decorators.py", line 21, in _wrapped_view
    if test_func(request.user):
AttributeError: 'long' object has no attribute 'user'
[2017-01-11 09:43:56,855] [Thread-78:2152] [django.request:256] [base:handle_uncaught_exception] [ERROR]- Internal Server Error: /ec/add_prod/
Traceback (most recent call last):
  File "C:\Python27\lib\site-packages\django-1.8.14-py2.7.egg\django\core\handlers\base.py", line 132, in get_response
    response = wrapped_callback(request, *callback_args, **callback_kwargs)
  File "C:\Python27\lib\site-packages\django-1.8.14-py2.7.egg\django\contrib\auth\decorators.py", line 22, in _wrapped_view
    return view_func(request, *args, **kwargs)
  File "D:\PycharmProjects\fec\apps\ec\views.py", line 163, in add_prod
    context_dict = get_cart_detail(cust_id)
  File "C:\Python27\lib\site-packages\django-1.8.14-py2.7.egg\django\contrib\auth\decorators.py", line 21, in _wrapped_view
    if test_func(request.user):
AttributeError: 'long' object has no attribute 'user'
[2017-01-11 09:49:06,776] [Thread-80:76] [django.request:256] [base:handle_uncaught_exception] [ERROR]- Internal Server Error: /ec/del_prod/
Traceback (most recent call last):
  File "C:\Python27\lib\site-packages\django-1.8.14-py2.7.egg\django\core\handlers\base.py", line 132, in get_response
    response = wrapped_callback(request, *callback_args, **callback_kwargs)
  File "C:\Python27\lib\site-packages\django-1.8.14-py2.7.egg\django\contrib\auth\decorators.py", line 22, in _wrapped_view
    return view_func(request, *args, **kwargs)
  File "D:\PycharmProjects\fec\apps\ec\views.py", line 189, in del_prod
    context_dict = get_cart_detail(cust_id)
  File "C:\Python27\lib\site-packages\django-1.8.14-py2.7.egg\django\contrib\auth\decorators.py", line 21, in _wrapped_view
    if test_func(request.user):
AttributeError: 'long' object has no attribute 'user'
[2017-01-11 09:50:52,167] [Thread-81:2060] [django.request:256] [base:handle_uncaught_exception] [ERROR]- Internal Server Error: /ec/add_prod/
Traceback (most recent call last):
  File "C:\Python27\lib\site-packages\django-1.8.14-py2.7.egg\django\core\handlers\base.py", line 132, in get_response
    response = wrapped_callback(request, *callback_args, **callback_kwargs)
  File "C:\Python27\lib\site-packages\django-1.8.14-py2.7.egg\django\contrib\auth\decorators.py", line 22, in _wrapped_view
    return view_func(request, *args, **kwargs)
  File "D:\PycharmProjects\fec\apps\ec\views.py", line 163, in add_prod
    context_dict = get_cart_detail(cust_id)
  File "C:\Python27\lib\site-packages\django-1.8.14-py2.7.egg\django\contrib\auth\decorators.py", line 21, in _wrapped_view
    if test_func(request.user):
AttributeError: 'long' object has no attribute 'user'
[2017-01-11 10:12:04,009] [Thread-9:3268] [django.request:256] [base:handle_uncaught_exception] [ERROR]- Internal Server Error: /ec/add_prod/
Traceback (most recent call last):
  File "C:\Python27\lib\site-packages\django-1.8.14-py2.7.egg\django\core\handlers\base.py", line 132, in get_response
    response = wrapped_callback(request, *callback_args, **callback_kwargs)
  File "C:\Python27\lib\site-packages\django-1.8.14-py2.7.egg\django\contrib\auth\decorators.py", line 22, in _wrapped_view
    return view_func(request, *args, **kwargs)
  File "D:\PycharmProjects\fec\apps\ec\views.py", line 164, in add_prod
    context_dict = get_cart_detail(cust_id)
  File "C:\Python27\lib\site-packages\django-1.8.14-py2.7.egg\django\contrib\auth\decorators.py", line 21, in _wrapped_view
    if test_func(request.user):
AttributeError: 'long' object has no attribute 'user'
[2017-01-11 13:55:59,957] [Thread-3:3652] [django.request:170] [base:get_response] [WARNING]- Not Found: /favicon.ico
[2017-01-11 15:26:17,595] [Thread-30:4172] [django.request:256] [base:handle_uncaught_exception] [ERROR]- Internal Server Error: /checkout_confirm/
Traceback (most recent call last):
  File "C:\Python27\lib\site-packages\django-1.8.14-py2.7.egg\django\core\handlers\base.py", line 132, in get_response
    response = wrapped_callback(request, *callback_args, **callback_kwargs)
  File "C:\Python27\lib\site-packages\django-1.8.14-py2.7.egg\django\contrib\auth\decorators.py", line 22, in _wrapped_view
    return view_func(request, *args, **kwargs)
  File "D:\PycharmProjects\fec\apps\ec\views.py", line 216, in checkout_confirm
    so = So.objects.filter(cust_id=cust.id, status=1)[0]
  File "C:\Python27\lib\site-packages\django-1.8.14-py2.7.egg\django\db\models\query.py", line 201, in __getitem__
    return list(qs)[0]
IndexError: list index out of range
[2017-01-11 15:26:21,453] [Thread-34:2676] [django.request:256] [base:handle_uncaught_exception] [ERROR]- Internal Server Error: /checkout_confirm/
Traceback (most recent call last):
  File "C:\Python27\lib\site-packages\django-1.8.14-py2.7.egg\django\core\handlers\base.py", line 132, in get_response
    response = wrapped_callback(request, *callback_args, **callback_kwargs)
  File "C:\Python27\lib\site-packages\django-1.8.14-py2.7.egg\django\contrib\auth\decorators.py", line 22, in _wrapped_view
    return view_func(request, *args, **kwargs)
  File "D:\PycharmProjects\fec\apps\ec\views.py", line 216, in checkout_confirm
    so = So.objects.filter(cust_id=cust.id, status=1)[0]
  File "C:\Python27\lib\site-packages\django-1.8.14-py2.7.egg\django\db\models\query.py", line 201, in __getitem__
    return list(qs)[0]
IndexError: list index out of range
[2017-01-11 18:09:41,464] [Thread-6:4800] [django.request:256] [base:handle_uncaught_exception] [ERROR]- Internal Server Error: /order_detail/33/
Traceback (most recent call last):
  File "C:\Python27\lib\site-packages\django-1.8.14-py2.7.egg\django\core\handlers\base.py", line 132, in get_response
    response = wrapped_callback(request, *callback_args, **callback_kwargs)
  File "C:\Python27\lib\site-packages\django-1.8.14-py2.7.egg\django\contrib\auth\decorators.py", line 22, in _wrapped_view
    return view_func(request, *args, **kwargs)
  File "D:\PycharmProjects\fec\apps\ec\views.py", line 298, in get_order_detail
    context_dict = get_order_info(so_id)
  File "D:\PycharmProjects\fec\apps\ec\views.py", line 287, in get_order_info
    status=888).values('so_id').annotate(total=Sum(F('qty') * F('price')))[0]['amount']
KeyError: 'amount'
[2017-01-11 18:09:43,724] [Thread-7:4948] [django.request:256] [base:handle_uncaught_exception] [ERROR]- Internal Server Error: /order_detail/33/
Traceback (most recent call last):
  File "C:\Python27\lib\site-packages\django-1.8.14-py2.7.egg\django\core\handlers\base.py", line 132, in get_response
    response = wrapped_callback(request, *callback_args, **callback_kwargs)
  File "C:\Python27\lib\site-packages\django-1.8.14-py2.7.egg\django\contrib\auth\decorators.py", line 22, in _wrapped_view
    return view_func(request, *args, **kwargs)
  File "D:\PycharmProjects\fec\apps\ec\views.py", line 298, in get_order_detail
    context_dict = get_order_info(so_id)
  File "D:\PycharmProjects\fec\apps\ec\views.py", line 287, in get_order_info
    status=888).values('so_id').annotate(total=Sum(F('qty') * F('price')))[0]['amount']
KeyError: 'amount'
[2017-01-11 18:19:23,158] [Thread-9:3556] [django.request:256] [base:handle_uncaught_exception] [ERROR]- Internal Server Error: /order_detail/34/
Traceback (most recent call last):
  File "C:\Python27\lib\site-packages\django-1.8.14-py2.7.egg\django\core\handlers\base.py", line 132, in get_response
    response = wrapped_callback(request, *callback_args, **callback_kwargs)
  File "C:\Python27\lib\site-packages\django-1.8.14-py2.7.egg\django\contrib\auth\decorators.py", line 21, in _wrapped_view
    if test_func(request.user):
  File "C:\Python27\lib\site-packages\django-1.8.14-py2.7.egg\django\contrib\auth\decorators.py", line 45, in <lambda>
    lambda u: u.is_authenticated(),
  File "C:\Python27\lib\site-packages\django-1.8.14-py2.7.egg\django\utils\functional.py", line 225, in inner
    self._setup()
  File "C:\Python27\lib\site-packages\django-1.8.14-py2.7.egg\django\utils\functional.py", line 376, in _setup
    self._wrapped = self._setupfunc()
  File "C:\Python27\lib\site-packages\django-1.8.14-py2.7.egg\django\contrib\auth\middleware.py", line 22, in <lambda>
    request.user = SimpleLazyObject(lambda: get_user(request))
  File "C:\Python27\lib\site-packages\django-1.8.14-py2.7.egg\django\contrib\auth\middleware.py", line 10, in get_user
    request._cached_user = auth.get_user(request)
  File "C:\Python27\lib\site-packages\django-1.8.14-py2.7.egg\django\contrib\auth\__init__.py", line 174, in get_user
    user = backend.get_user(user_id)
  File "C:\Python27\lib\site-packages\django-1.8.14-py2.7.egg\django\contrib\auth\backends.py", line 93, in get_user
    return UserModel._default_manager.get(pk=user_id)
  File "C:\Python27\lib\site-packages\django-1.8.14-py2.7.egg\django\db\models\manager.py", line 127, in manager_method
    return getattr(self.get_queryset(), name)(*args, **kwargs)
  File "C:\Python27\lib\site-packages\django-1.8.14-py2.7.egg\django\db\models\query.py", line 328, in get
    num = len(clone)
  File "C:\Python27\lib\site-packages\django-1.8.14-py2.7.egg\django\db\models\query.py", line 144, in __len__
    self._fetch_all()
  File "C:\Python27\lib\site-packages\django-1.8.14-py2.7.egg\django\db\models\query.py", line 965, in _fetch_all
    self._result_cache = list(self.iterator())
  File "C:\Python27\lib\site-packages\django-1.8.14-py2.7.egg\django\db\models\query.py", line 238, in iterator
    results = compiler.execute_sql()
  File "C:\Python27\lib\site-packages\django-1.8.14-py2.7.egg\django\db\models\sql\compiler.py", line 840, in execute_sql
    cursor.execute(sql, params)
  File "C:\Python27\lib\site-packages\django-1.8.14-py2.7.egg\django\db\backends\utils.py", line 79, in execute
    return super(CursorDebugWrapper, self).execute(sql, params)
  File "C:\Python27\lib\site-packages\django-1.8.14-py2.7.egg\django\db\backends\utils.py", line 64, in execute
    return self.cursor.execute(sql, params)
  File "C:\Python27\lib\site-packages\django-1.8.14-py2.7.egg\django\db\utils.py", line 98, in __exit__
    six.reraise(dj_exc_type, dj_exc_value, traceback)
  File "C:\Python27\lib\site-packages\django-1.8.14-py2.7.egg\django\db\backends\utils.py", line 64, in execute
    return self.cursor.execute(sql, params)
  File "C:\Python27\lib\site-packages\django-1.8.14-py2.7.egg\django\db\backends\mysql\base.py", line 124, in execute
    return self.cursor.execute(query, args)
  File "C:\Python27\lib\site-packages\MySQLdb\cursors.py", line 174, in execute
    self.errorhandler(self, exc, value)
  File "C:\Python27\lib\site-packages\MySQLdb\connections.py", line 36, in defaulterrorhandler
    raise errorclass, errorvalue
OperationalError: (2013, 'Lost connection to MySQL server during query')
[2017-01-12 10:01:37,457] [Thread-14:5028] [django.request:256] [base:handle_uncaught_exception] [ERROR]- Internal Server Error: /ec/add_prod/
Traceback (most recent call last):
  File "C:\Python27\lib\site-packages\django-1.8.14-py2.7.egg\django\core\handlers\base.py", line 132, in get_response
    response = wrapped_callback(request, *callback_args, **callback_kwargs)
  File "C:\Python27\lib\site-packages\django-1.8.14-py2.7.egg\django\contrib\auth\decorators.py", line 22, in _wrapped_view
    return view_func(request, *args, **kwargs)
  File "D:\PycharmProjects\fec\apps\ec\views.py", line 154, in add_prod
    prod = Prod.objects.get(id=request.POST.get('prod_id'))
  File "C:\Python27\lib\site-packages\django-1.8.14-py2.7.egg\django\db\models\manager.py", line 127, in manager_method
    return getattr(self.get_queryset(), name)(*args, **kwargs)
  File "C:\Python27\lib\site-packages\django-1.8.14-py2.7.egg\django\db\models\query.py", line 334, in get
    self.model._meta.object_name
DoesNotExist: Prod matching query does not exist.
[2017-01-12 10:01:42,164] [Thread-13:2192] [django.request:256] [base:handle_uncaught_exception] [ERROR]- Internal Server Error: /ec/add_prod/
Traceback (most recent call last):
  File "C:\Python27\lib\site-packages\django-1.8.14-py2.7.egg\django\core\handlers\base.py", line 132, in get_response
    response = wrapped_callback(request, *callback_args, **callback_kwargs)
  File "C:\Python27\lib\site-packages\django-1.8.14-py2.7.egg\django\contrib\auth\decorators.py", line 22, in _wrapped_view
    return view_func(request, *args, **kwargs)
  File "D:\PycharmProjects\fec\apps\ec\views.py", line 154, in add_prod
    prod = Prod.objects.get(id=request.POST.get('prod_id'))
  File "C:\Python27\lib\site-packages\django-1.8.14-py2.7.egg\django\db\models\manager.py", line 127, in manager_method
    return getattr(self.get_queryset(), name)(*args, **kwargs)
  File "C:\Python27\lib\site-packages\django-1.8.14-py2.7.egg\django\db\models\query.py", line 334, in get
    self.model._meta.object_name
DoesNotExist: Prod matching query does not exist.
[2017-01-12 10:01:45,003] [Thread-15:3664] [django.request:256] [base:handle_uncaught_exception] [ERROR]- Internal Server Error: /ec/add_prod/
Traceback (most recent call last):
  File "C:\Python27\lib\site-packages\django-1.8.14-py2.7.egg\django\core\handlers\base.py", line 132, in get_response
    response = wrapped_callback(request, *callback_args, **callback_kwargs)
  File "C:\Python27\lib\site-packages\django-1.8.14-py2.7.egg\django\contrib\auth\decorators.py", line 22, in _wrapped_view
    return view_func(request, *args, **kwargs)
  File "D:\PycharmProjects\fec\apps\ec\views.py", line 154, in add_prod
    prod = Prod.objects.get(id=request.POST.get('prod_id'))
  File "C:\Python27\lib\site-packages\django-1.8.14-py2.7.egg\django\db\models\manager.py", line 127, in manager_method
    return getattr(self.get_queryset(), name)(*args, **kwargs)
  File "C:\Python27\lib\site-packages\django-1.8.14-py2.7.egg\django\db\models\query.py", line 334, in get
    self.model._meta.object_name
DoesNotExist: Prod matching query does not exist.
[2017-01-12 10:01:46,686] [Thread-16:180] [django.request:256] [base:handle_uncaught_exception] [ERROR]- Internal Server Error: /ec/add_prod/
Traceback (most recent call last):
  File "C:\Python27\lib\site-packages\django-1.8.14-py2.7.egg\django\core\handlers\base.py", line 132, in get_response
    response = wrapped_callback(request, *callback_args, **callback_kwargs)
  File "C:\Python27\lib\site-packages\django-1.8.14-py2.7.egg\django\contrib\auth\decorators.py", line 22, in _wrapped_view
    return view_func(request, *args, **kwargs)
  File "D:\PycharmProjects\fec\apps\ec\views.py", line 154, in add_prod
    prod = Prod.objects.get(id=request.POST.get('prod_id'))
  File "C:\Python27\lib\site-packages\django-1.8.14-py2.7.egg\django\db\models\manager.py", line 127, in manager_method
    return getattr(self.get_queryset(), name)(*args, **kwargs)
  File "C:\Python27\lib\site-packages\django-1.8.14-py2.7.egg\django\db\models\query.py", line 334, in get
    self.model._meta.object_name
DoesNotExist: Prod matching query does not exist.
[2017-01-12 10:02:29,904] [Thread-30:1492] [django.request:256] [base:handle_uncaught_exception] [ERROR]- Internal Server Error: /ec/add_prod/
Traceback (most recent call last):
  File "C:\Python27\lib\site-packages\django-1.8.14-py2.7.egg\django\core\handlers\base.py", line 132, in get_response
    response = wrapped_callback(request, *callback_args, **callback_kwargs)
  File "C:\Python27\lib\site-packages\django-1.8.14-py2.7.egg\django\contrib\auth\decorators.py", line 22, in _wrapped_view
    return view_func(request, *args, **kwargs)
  File "D:\PycharmProjects\fec\apps\ec\views.py", line 154, in add_prod
    prod = Prod.objects.get(id=request.POST.get('prod_id'))
  File "C:\Python27\lib\site-packages\django-1.8.14-py2.7.egg\django\db\models\manager.py", line 127, in manager_method
    return getattr(self.get_queryset(), name)(*args, **kwargs)
  File "C:\Python27\lib\site-packages\django-1.8.14-py2.7.egg\django\db\models\query.py", line 334, in get
    self.model._meta.object_name
DoesNotExist: Prod matching query does not exist.
[2017-01-12 10:14:04,526] [Thread-16:4520] [django.request:256] [base:handle_uncaught_exception] [ERROR]- Internal Server Error: /ec/rmv_prod/
Traceback (most recent call last):
  File "C:\Python27\lib\site-packages\django-1.8.14-py2.7.egg\django\core\handlers\base.py", line 132, in get_response
    response = wrapped_callback(request, *callback_args, **callback_kwargs)
  File "C:\Python27\lib\site-packages\django-1.8.14-py2.7.egg\django\contrib\auth\decorators.py", line 22, in _wrapped_view
    return view_func(request, *args, **kwargs)
  File "D:\PycharmProjects\fec\apps\ec\views.py", line 213, in rmv_prod
    context_dict = get_cart_info(cust_id)
  File "D:\PycharmProjects\fec\apps\ec\views.py", line 128, in get_cart_info
    status=1).values('so_id').annotate(total=Sum(F('qty')))[0]['total']
  File "C:\Python27\lib\site-packages\django-1.8.14-py2.7.egg\django\db\models\query.py", line 201, in __getitem__
    return list(qs)[0]
IndexError: list index out of range
[2017-01-12 10:15:25,453] [Thread-2:4796] [django.request:256] [base:handle_uncaught_exception] [ERROR]- Internal Server Error: /cart/
Traceback (most recent call last):
  File "C:\Python27\lib\site-packages\django-1.8.14-py2.7.egg\django\core\handlers\base.py", line 132, in get_response
    response = wrapped_callback(request, *callback_args, **callback_kwargs)
  File "C:\Python27\lib\site-packages\django-1.8.14-py2.7.egg\django\contrib\auth\decorators.py", line 22, in _wrapped_view
    return view_func(request, *args, **kwargs)
  File "D:\PycharmProjects\fec\apps\ec\views.py", line 144, in get_cart_detail
    context_dict = get_cart_info(cust_id)
  File "D:\PycharmProjects\fec\apps\ec\views.py", line 128, in get_cart_info
    status=1).values('so_id').annotate(total=Sum(F('qty')))[0]['total']
  File "C:\Python27\lib\site-packages\django-1.8.14-py2.7.egg\django\db\models\query.py", line 201, in __getitem__
    return list(qs)[0]
IndexError: list index out of range
[2017-01-12 10:15:45,407] [Thread-4:4136] [django.request:256] [base:handle_uncaught_exception] [ERROR]- Internal Server Error: /cart/
Traceback (most recent call last):
  File "C:\Python27\lib\site-packages\django-1.8.14-py2.7.egg\django\core\handlers\base.py", line 132, in get_response
    response = wrapped_callback(request, *callback_args, **callback_kwargs)
  File "C:\Python27\lib\site-packages\django-1.8.14-py2.7.egg\django\contrib\auth\decorators.py", line 22, in _wrapped_view
    return view_func(request, *args, **kwargs)
  File "D:\PycharmProjects\fec\apps\ec\views.py", line 144, in get_cart_detail
    context_dict = get_cart_info(cust_id)
  File "D:\PycharmProjects\fec\apps\ec\views.py", line 128, in get_cart_info
    status=1).values('so_id').annotate(total=Sum(F('qty')))[0]['total']
  File "C:\Python27\lib\site-packages\django-1.8.14-py2.7.egg\django\db\models\query.py", line 201, in __getitem__
    return list(qs)[0]
IndexError: list index out of range
[2017-01-12 10:33:06,766] [Thread-7:2788] [django.request:256] [base:handle_uncaught_exception] [ERROR]- Internal Server Error: /ec/rmv_prod/
Traceback (most recent call last):
  File "C:\Python27\lib\site-packages\django-1.8.14-py2.7.egg\django\core\handlers\base.py", line 132, in get_response
    response = wrapped_callback(request, *callback_args, **callback_kwargs)
  File "C:\Python27\lib\site-packages\django-1.8.14-py2.7.egg\django\contrib\auth\decorators.py", line 22, in _wrapped_view
    return view_func(request, *args, **kwargs)
  File "D:\PycharmProjects\fec\apps\ec\views.py", line 208, in rmv_prod
    so_id=so_id).distinct('prod_id').count()
  File "C:\Python27\lib\site-packages\django-1.8.14-py2.7.egg\django\db\models\query.py", line 318, in count
    return self.query.get_count(using=self.db)
  File "C:\Python27\lib\site-packages\django-1.8.14-py2.7.egg\django\db\models\sql\query.py", line 466, in get_count
    number = obj.get_aggregation(using, ['__count'])['__count']
  File "C:\Python27\lib\site-packages\django-1.8.14-py2.7.egg\django\db\models\sql\query.py", line 430, in get_aggregation
    outer_query.add_subquery(inner_query, using)
  File "C:\Python27\lib\site-packages\django-1.8.14-py2.7.egg\django\db\models\sql\subqueries.py", line 213, in add_subquery
    subquery=True,
  File "C:\Python27\lib\site-packages\django-1.8.14-py2.7.egg\django\db\models\sql\compiler.py", line 393, in as_sql
    result.append(self.connection.ops.distinct_sql(distinct_fields))
  File "C:\Python27\lib\site-packages\django-1.8.14-py2.7.egg\django\db\backends\base\operations.py", line 132, in distinct_sql
    raise NotImplementedError('DISTINCT ON fields is not supported by this database backend')
NotImplementedError: DISTINCT ON fields is not supported by this database backend
[2017-01-12 10:33:47,747] [Thread-9:4252] [django.request:256] [base:handle_uncaught_exception] [ERROR]- Internal Server Error: /ec/rmv_prod/
Traceback (most recent call last):
  File "C:\Python27\lib\site-packages\django-1.8.14-py2.7.egg\django\core\handlers\base.py", line 132, in get_response
    response = wrapped_callback(request, *callback_args, **callback_kwargs)
  File "C:\Python27\lib\site-packages\django-1.8.14-py2.7.egg\django\contrib\auth\decorators.py", line 22, in _wrapped_view
    return view_func(request, *args, **kwargs)
  File "D:\PycharmProjects\fec\apps\ec\views.py", line 208, in rmv_prod
    so_id=so_id).distinct('prod_id').count()
  File "C:\Python27\lib\site-packages\django-1.8.14-py2.7.egg\django\db\models\query.py", line 318, in count
    return self.query.get_count(using=self.db)
  File "C:\Python27\lib\site-packages\django-1.8.14-py2.7.egg\django\db\models\sql\query.py", line 466, in get_count
    number = obj.get_aggregation(using, ['__count'])['__count']
  File "C:\Python27\lib\site-packages\django-1.8.14-py2.7.egg\django\db\models\sql\query.py", line 430, in get_aggregation
    outer_query.add_subquery(inner_query, using)
  File "C:\Python27\lib\site-packages\django-1.8.14-py2.7.egg\django\db\models\sql\subqueries.py", line 213, in add_subquery
    subquery=True,
  File "C:\Python27\lib\site-packages\django-1.8.14-py2.7.egg\django\db\models\sql\compiler.py", line 393, in as_sql
    result.append(self.connection.ops.distinct_sql(distinct_fields))
  File "C:\Python27\lib\site-packages\django-1.8.14-py2.7.egg\django\db\backends\base\operations.py", line 132, in distinct_sql
    raise NotImplementedError('DISTINCT ON fields is not supported by this database backend')
NotImplementedError: DISTINCT ON fields is not supported by this database backend
[2017-01-12 10:35:49,599] [Thread-6:3000] [django.request:256] [base:handle_uncaught_exception] [ERROR]- Internal Server Error: /ec/rmv_prod/
Traceback (most recent call last):
  File "C:\Python27\lib\site-packages\django-1.8.14-py2.7.egg\django\core\handlers\base.py", line 132, in get_response
    response = wrapped_callback(request, *callback_args, **callback_kwargs)
  File "C:\Python27\lib\site-packages\django-1.8.14-py2.7.egg\django\contrib\auth\decorators.py", line 22, in _wrapped_view
    return view_func(request, *args, **kwargs)
  File "D:\PycharmProjects\fec\apps\ec\views.py", line 210, in rmv_prod
    so_id=so_id).distinct('prod_id').count()
  File "C:\Python27\lib\site-packages\django-1.8.14-py2.7.egg\django\db\models\query.py", line 318, in count
    return self.query.get_count(using=self.db)
  File "C:\Python27\lib\site-packages\django-1.8.14-py2.7.egg\django\db\models\sql\query.py", line 466, in get_count
    number = obj.get_aggregation(using, ['__count'])['__count']
  File "C:\Python27\lib\site-packages\django-1.8.14-py2.7.egg\django\db\models\sql\query.py", line 430, in get_aggregation
    outer_query.add_subquery(inner_query, using)
  File "C:\Python27\lib\site-packages\django-1.8.14-py2.7.egg\django\db\models\sql\subqueries.py", line 213, in add_subquery
    subquery=True,
  File "C:\Python27\lib\site-packages\django-1.8.14-py2.7.egg\django\db\models\sql\compiler.py", line 393, in as_sql
    result.append(self.connection.ops.distinct_sql(distinct_fields))
  File "C:\Python27\lib\site-packages\django-1.8.14-py2.7.egg\django\db\backends\base\operations.py", line 132, in distinct_sql
    raise NotImplementedError('DISTINCT ON fields is not supported by this database backend')
NotImplementedError: DISTINCT ON fields is not supported by this database backend
[2017-01-12 14:38:42,844] [Thread-6:1852] [django.request:256] [base:handle_uncaught_exception] [ERROR]- Internal Server Error: /ec/rmv_prod/
Traceback (most recent call last):
  File "C:\Python27\lib\site-packages\django-1.8.14-py2.7.egg\django\core\handlers\base.py", line 132, in get_response
    response = wrapped_callback(request, *callback_args, **callback_kwargs)
  File "C:\Python27\lib\site-packages\django-1.8.14-py2.7.egg\django\contrib\auth\decorators.py", line 22, in _wrapped_view
    return view_func(request, *args, **kwargs)
  File "D:\PycharmProjects\fec\apps\ec\views.py", line 209, in rmv_prod
    so_id=so_id).count('prod_id', distinct=True)
TypeError: count() takes exactly 1 argument (3 given)
[2017-01-12 14:44:50,940] [Thread-6:4308] [django.request:256] [base:handle_uncaught_exception] [ERROR]- Internal Server Error: /ec/rmv_prod/
Traceback (most recent call last):
  File "C:\Python27\lib\site-packages\django-1.8.14-py2.7.egg\django\core\handlers\base.py", line 132, in get_response
    response = wrapped_callback(request, *callback_args, **callback_kwargs)
  File "C:\Python27\lib\site-packages\django-1.8.14-py2.7.egg\django\contrib\auth\decorators.py", line 22, in _wrapped_view
    return view_func(request, *args, **kwargs)
  File "D:\PycharmProjects\fec\apps\ec\views.py", line 209, in rmv_prod
    so_id=so_id).annotate(count=Count('prod_id', distinct=True))[0]['count']
TypeError: 'Sol' object has no attribute '__getitem__'
[2017-01-12 14:44:58,505] [Thread-10:2248] [django.request:256] [base:handle_uncaught_exception] [ERROR]- Internal Server Error: /ec/rmv_prod/
Traceback (most recent call last):
  File "C:\Python27\lib\site-packages\django-1.8.14-py2.7.egg\django\core\handlers\base.py", line 132, in get_response
    response = wrapped_callback(request, *callback_args, **callback_kwargs)
  File "C:\Python27\lib\site-packages\django-1.8.14-py2.7.egg\django\contrib\auth\decorators.py", line 22, in _wrapped_view
    return view_func(request, *args, **kwargs)
  File "D:\PycharmProjects\fec\apps\ec\views.py", line 209, in rmv_prod
    so_id=so_id).annotate(count=Count('prod_id', distinct=True))[0]['count']
TypeError: 'Sol' object has no attribute '__getitem__'
[2017-01-12 15:07:41,288] [Thread-10:4164] [django.request:256] [base:handle_uncaught_exception] [ERROR]- Internal Server Error: /ec/rmv_prod/
Traceback (most recent call last):
  File "C:\Python27\lib\site-packages\django-1.8.14-py2.7.egg\django\core\handlers\base.py", line 132, in get_response
    response = wrapped_callback(request, *callback_args, **callback_kwargs)
  File "C:\Python27\lib\site-packages\django-1.8.14-py2.7.egg\django\contrib\auth\decorators.py", line 22, in _wrapped_view
    return view_func(request, *args, **kwargs)
  File "D:\PycharmProjects\fec\apps\ec\views.py", line 209, in rmv_prod
    so_id=so_id).annotate(count=Count('prod_id', distinct=True))[0]['count']
TypeError: 'Sol' object has no attribute '__getitem__'
[2017-01-12 15:24:37,298] [Thread-4:4352] [django.request:256] [base:handle_uncaught_exception] [ERROR]- Internal Server Error: /ec/rmv_prod/
Traceback (most recent call last):
  File "C:\Python27\lib\site-packages\django-1.8.14-py2.7.egg\django\core\handlers\base.py", line 132, in get_response
    response = wrapped_callback(request, *callback_args, **callback_kwargs)
  File "C:\Python27\lib\site-packages\django-1.8.14-py2.7.egg\django\contrib\auth\decorators.py", line 22, in _wrapped_view
    return view_func(request, *args, **kwargs)
  File "D:\PycharmProjects\fec\apps\ec\views.py", line 209, in rmv_prod
    so_id=so_id).values('prod_id').distinct().annotate(count=Count())[0]['count']
TypeError: __init__() takes at least 2 arguments (1 given)
[2017-01-12 15:25:09,453] [Thread-9:5028] [django.request:256] [base:handle_uncaught_exception] [ERROR]- Internal Server Error: /ec/rmv_prod/
Traceback (most recent call last):
  File "C:\Python27\lib\site-packages\django-1.8.14-py2.7.egg\django\core\handlers\base.py", line 132, in get_response
    response = wrapped_callback(request, *callback_args, **callback_kwargs)
  File "C:\Python27\lib\site-packages\django-1.8.14-py2.7.egg\django\contrib\auth\decorators.py", line 22, in _wrapped_view
    return view_func(request, *args, **kwargs)
  File "D:\PycharmProjects\fec\apps\ec\views.py", line 209, in rmv_prod
    so_id=so_id).values('prod_id').distinct().annotate(count=Count())[0]['count']
TypeError: __init__() takes at least 2 arguments (1 given)
[2017-01-13 15:50:05,321] [Thread-2:4528] [django.request:256] [base:handle_uncaught_exception] [ERROR]- Internal Server Error: /
Traceback (most recent call last):
  File "C:\Python27\lib\site-packages\django-1.8.14-py2.7.egg\django\core\handlers\base.py", line 132, in get_response
    response = wrapped_callback(request, *callback_args, **callback_kwargs)
  File "D:\PycharmProjects\fec\apps\ec\views.py", line 33, in get_prod_list
    context_dict)
  File "C:\Python27\lib\site-packages\django-1.8.14-py2.7.egg\django\shortcuts.py", line 67, in render
    template_name, context, request=request, using=using)
  File "C:\Python27\lib\site-packages\django-1.8.14-py2.7.egg\django\template\loader.py", line 99, in render_to_string
    return template.render(context, request)
  File "C:\Python27\lib\site-packages\django-1.8.14-py2.7.egg\django\template\backends\django.py", line 74, in render
    return self.template.render(context)
  File "C:\Python27\lib\site-packages\django-1.8.14-py2.7.egg\django\template\base.py", line 210, in render
    return self._render(context)
  File "C:\Python27\lib\site-packages\django-1.8.14-py2.7.egg\django\template\base.py", line 202, in _render
    return self.nodelist.render(context)
  File "C:\Python27\lib\site-packages\django-1.8.14-py2.7.egg\django\template\base.py", line 905, in render
    bit = self.render_node(node, context)
  File "C:\Python27\lib\site-packages\django-1.8.14-py2.7.egg\django\template\debug.py", line 79, in render_node
    return node.render(context)
  File "C:\Python27\lib\site-packages\django-1.8.14-py2.7.egg\django\template\loader_tags.py", line 135, in render
    return compiled_parent._render(context)
  File "C:\Python27\lib\site-packages\django-1.8.14-py2.7.egg\django\template\base.py", line 202, in _render
    return self.nodelist.render(context)
  File "C:\Python27\lib\site-packages\django-1.8.14-py2.7.egg\django\template\base.py", line 905, in render
    bit = self.render_node(node, context)
  File "C:\Python27\lib\site-packages\django-1.8.14-py2.7.egg\django\template\debug.py", line 79, in render_node
    return node.render(context)
  File "C:\Python27\lib\site-packages\django-1.8.14-py2.7.egg\django\template\loader_tags.py", line 135, in render
    return compiled_parent._render(context)
  File "C:\Python27\lib\site-packages\django-1.8.14-py2.7.egg\django\template\base.py", line 202, in _render
    return self.nodelist.render(context)
  File "C:\Python27\lib\site-packages\django-1.8.14-py2.7.egg\django\template\base.py", line 905, in render
    bit = self.render_node(node, context)
  File "C:\Python27\lib\site-packages\django-1.8.14-py2.7.egg\django\template\debug.py", line 79, in render_node
    return node.render(context)
  File "C:\Python27\lib\site-packages\django-1.8.14-py2.7.egg\django\template\loader_tags.py", line 65, in render
    result = block.nodelist.render(context)
  File "C:\Python27\lib\site-packages\django-1.8.14-py2.7.egg\django\template\base.py", line 905, in render
    bit = self.render_node(node, context)
  File "C:\Python27\lib\site-packages\django-1.8.14-py2.7.egg\django\template\debug.py", line 79, in render_node
    return node.render(context)
  File "C:\Python27\lib\site-packages\django-1.8.14-py2.7.egg\django\template\loader_tags.py", line 159, in render
    return template.render(context)
  File "C:\Python27\lib\site-packages\django-1.8.14-py2.7.egg\django\template\base.py", line 212, in render
    return self._render(context)
  File "C:\Python27\lib\site-packages\django-1.8.14-py2.7.egg\django\template\base.py", line 202, in _render
    return self.nodelist.render(context)
  File "C:\Python27\lib\site-packages\django-1.8.14-py2.7.egg\django\template\base.py", line 905, in render
    bit = self.render_node(node, context)
  File "C:\Python27\lib\site-packages\django-1.8.14-py2.7.egg\django\template\debug.py", line 79, in render_node
    return node.render(context)
  File "C:\Python27\lib\site-packages\django-1.8.14-py2.7.egg\django\template\defaulttags.py", line 507, in render
    six.reraise(*exc_info)
  File "C:\Python27\lib\site-packages\django-1.8.14-py2.7.egg\django\template\defaulttags.py", line 493, in render
    url = reverse(view_name, args=args, kwargs=kwargs, current_app=current_app)
  File "C:\Python27\lib\site-packages\django-1.8.14-py2.7.egg\django\core\urlresolvers.py", line 578, in reverse
    return force_text(iri_to_uri(resolver._reverse_with_prefix(view, prefix, *args, **kwargs)))
  File "C:\Python27\lib\site-packages\django-1.8.14-py2.7.egg\django\core\urlresolvers.py", line 495, in _reverse_with_prefix
    (lookup_view_s, args, kwargs, len(patterns), patterns))
NoReverseMatch: Reverse for 'prod_list_by_category' with arguments '()' and keyword arguments '{u'category': u'\u7259\u818f'}' not found. 1 pattern(s) tried: ['prod_list/(?P<category>\\s+)']
[2017-01-13 15:51:48,937] [Thread-4:2092] [django.request:256] [base:handle_uncaught_exception] [ERROR]- Internal Server Error: /
Traceback (most recent call last):
  File "C:\Python27\lib\site-packages\django-1.8.14-py2.7.egg\django\core\handlers\base.py", line 132, in get_response
    response = wrapped_callback(request, *callback_args, **callback_kwargs)
  File "D:\PycharmProjects\fec\apps\ec\views.py", line 33, in get_prod_list
    context_dict)
  File "C:\Python27\lib\site-packages\django-1.8.14-py2.7.egg\django\shortcuts.py", line 67, in render
    template_name, context, request=request, using=using)
  File "C:\Python27\lib\site-packages\django-1.8.14-py2.7.egg\django\template\loader.py", line 99, in render_to_string
    return template.render(context, request)
  File "C:\Python27\lib\site-packages\django-1.8.14-py2.7.egg\django\template\backends\django.py", line 74, in render
    return self.template.render(context)
  File "C:\Python27\lib\site-packages\django-1.8.14-py2.7.egg\django\template\base.py", line 210, in render
    return self._render(context)
  File "C:\Python27\lib\site-packages\django-1.8.14-py2.7.egg\django\template\base.py", line 202, in _render
    return self.nodelist.render(context)
  File "C:\Python27\lib\site-packages\django-1.8.14-py2.7.egg\django\template\base.py", line 905, in render
    bit = self.render_node(node, context)
  File "C:\Python27\lib\site-packages\django-1.8.14-py2.7.egg\django\template\debug.py", line 79, in render_node
    return node.render(context)
  File "C:\Python27\lib\site-packages\django-1.8.14-py2.7.egg\django\template\loader_tags.py", line 135, in render
    return compiled_parent._render(context)
  File "C:\Python27\lib\site-packages\django-1.8.14-py2.7.egg\django\template\base.py", line 202, in _render
    return self.nodelist.render(context)
  File "C:\Python27\lib\site-packages\django-1.8.14-py2.7.egg\django\template\base.py", line 905, in render
    bit = self.render_node(node, context)
  File "C:\Python27\lib\site-packages\django-1.8.14-py2.7.egg\django\template\debug.py", line 79, in render_node
    return node.render(context)
  File "C:\Python27\lib\site-packages\django-1.8.14-py2.7.egg\django\template\loader_tags.py", line 135, in render
    return compiled_parent._render(context)
  File "C:\Python27\lib\site-packages\django-1.8.14-py2.7.egg\django\template\base.py", line 202, in _render
    return self.nodelist.render(context)
  File "C:\Python27\lib\site-packages\django-1.8.14-py2.7.egg\django\template\base.py", line 905, in render
    bit = self.render_node(node, context)
  File "C:\Python27\lib\site-packages\django-1.8.14-py2.7.egg\django\template\debug.py", line 79, in render_node
    return node.render(context)
  File "C:\Python27\lib\site-packages\django-1.8.14-py2.7.egg\django\template\loader_tags.py", line 65, in render
    result = block.nodelist.render(context)
  File "C:\Python27\lib\site-packages\django-1.8.14-py2.7.egg\django\template\base.py", line 905, in render
    bit = self.render_node(node, context)
  File "C:\Python27\lib\site-packages\django-1.8.14-py2.7.egg\django\template\debug.py", line 79, in render_node
    return node.render(context)
  File "C:\Python27\lib\site-packages\django-1.8.14-py2.7.egg\django\template\loader_tags.py", line 159, in render
    return template.render(context)
  File "C:\Python27\lib\site-packages\django-1.8.14-py2.7.egg\django\template\base.py", line 212, in render
    return self._render(context)
  File "C:\Python27\lib\site-packages\django-1.8.14-py2.7.egg\django\template\base.py", line 202, in _render
    return self.nodelist.render(context)
  File "C:\Python27\lib\site-packages\django-1.8.14-py2.7.egg\django\template\base.py", line 905, in render
    bit = self.render_node(node, context)
  File "C:\Python27\lib\site-packages\django-1.8.14-py2.7.egg\django\template\debug.py", line 79, in render_node
    return node.render(context)
  File "C:\Python27\lib\site-packages\django-1.8.14-py2.7.egg\django\template\defaulttags.py", line 507, in render
    six.reraise(*exc_info)
  File "C:\Python27\lib\site-packages\django-1.8.14-py2.7.egg\django\template\defaulttags.py", line 493, in render
    url = reverse(view_name, args=args, kwargs=kwargs, current_app=current_app)
  File "C:\Python27\lib\site-packages\django-1.8.14-py2.7.egg\django\core\urlresolvers.py", line 578, in reverse
    return force_text(iri_to_uri(resolver._reverse_with_prefix(view, prefix, *args, **kwargs)))
  File "C:\Python27\lib\site-packages\django-1.8.14-py2.7.egg\django\core\urlresolvers.py", line 495, in _reverse_with_prefix
    (lookup_view_s, args, kwargs, len(patterns), patterns))
NoReverseMatch: Reverse for 'prod_list_by_category' with arguments '()' and keyword arguments '{u'category': u'yagao'}' not found. 1 pattern(s) tried: ['prod_list/(?P<category>\\s+)']
[2017-01-13 15:51:54,839] [Thread-5:4836] [django.request:256] [base:handle_uncaught_exception] [ERROR]- Internal Server Error: /
Traceback (most recent call last):
  File "C:\Python27\lib\site-packages\django-1.8.14-py2.7.egg\django\core\handlers\base.py", line 132, in get_response
    response = wrapped_callback(request, *callback_args, **callback_kwargs)
  File "D:\PycharmProjects\fec\apps\ec\views.py", line 33, in get_prod_list
    context_dict)
  File "C:\Python27\lib\site-packages\django-1.8.14-py2.7.egg\django\shortcuts.py", line 67, in render
    template_name, context, request=request, using=using)
  File "C:\Python27\lib\site-packages\django-1.8.14-py2.7.egg\django\template\loader.py", line 99, in render_to_string
    return template.render(context, request)
  File "C:\Python27\lib\site-packages\django-1.8.14-py2.7.egg\django\template\backends\django.py", line 74, in render
    return self.template.render(context)
  File "C:\Python27\lib\site-packages\django-1.8.14-py2.7.egg\django\template\base.py", line 210, in render
    return self._render(context)
  File "C:\Python27\lib\site-packages\django-1.8.14-py2.7.egg\django\template\base.py", line 202, in _render
    return self.nodelist.render(context)
  File "C:\Python27\lib\site-packages\django-1.8.14-py2.7.egg\django\template\base.py", line 905, in render
    bit = self.render_node(node, context)
  File "C:\Python27\lib\site-packages\django-1.8.14-py2.7.egg\django\template\debug.py", line 79, in render_node
    return node.render(context)
  File "C:\Python27\lib\site-packages\django-1.8.14-py2.7.egg\django\template\loader_tags.py", line 135, in render
    return compiled_parent._render(context)
  File "C:\Python27\lib\site-packages\django-1.8.14-py2.7.egg\django\template\base.py", line 202, in _render
    return self.nodelist.render(context)
  File "C:\Python27\lib\site-packages\django-1.8.14-py2.7.egg\django\template\base.py", line 905, in render
    bit = self.render_node(node, context)
  File "C:\Python27\lib\site-packages\django-1.8.14-py2.7.egg\django\template\debug.py", line 79, in render_node
    return node.render(context)
  File "C:\Python27\lib\site-packages\django-1.8.14-py2.7.egg\django\template\loader_tags.py", line 135, in render
    return compiled_parent._render(context)
  File "C:\Python27\lib\site-packages\django-1.8.14-py2.7.egg\django\template\base.py", line 202, in _render
    return self.nodelist.render(context)
  File "C:\Python27\lib\site-packages\django-1.8.14-py2.7.egg\django\template\base.py", line 905, in render
    bit = self.render_node(node, context)
  File "C:\Python27\lib\site-packages\django-1.8.14-py2.7.egg\django\template\debug.py", line 79, in render_node
    return node.render(context)
  File "C:\Python27\lib\site-packages\django-1.8.14-py2.7.egg\django\template\loader_tags.py", line 65, in render
    result = block.nodelist.render(context)
  File "C:\Python27\lib\site-packages\django-1.8.14-py2.7.egg\django\template\base.py", line 905, in render
    bit = self.render_node(node, context)
  File "C:\Python27\lib\site-packages\django-1.8.14-py2.7.egg\django\template\debug.py", line 79, in render_node
    return node.render(context)
  File "C:\Python27\lib\site-packages\django-1.8.14-py2.7.egg\django\template\loader_tags.py", line 159, in render
    return template.render(context)
  File "C:\Python27\lib\site-packages\django-1.8.14-py2.7.egg\django\template\base.py", line 212, in render
    return self._render(context)
  File "C:\Python27\lib\site-packages\django-1.8.14-py2.7.egg\django\template\base.py", line 202, in _render
    return self.nodelist.render(context)
  File "C:\Python27\lib\site-packages\django-1.8.14-py2.7.egg\django\template\base.py", line 905, in render
    bit = self.render_node(node, context)
  File "C:\Python27\lib\site-packages\django-1.8.14-py2.7.egg\django\template\debug.py", line 79, in render_node
    return node.render(context)
  File "C:\Python27\lib\site-packages\django-1.8.14-py2.7.egg\django\template\defaulttags.py", line 507, in render
    six.reraise(*exc_info)
  File "C:\Python27\lib\site-packages\django-1.8.14-py2.7.egg\django\template\defaulttags.py", line 493, in render
    url = reverse(view_name, args=args, kwargs=kwargs, current_app=current_app)
  File "C:\Python27\lib\site-packages\django-1.8.14-py2.7.egg\django\core\urlresolvers.py", line 578, in reverse
    return force_text(iri_to_uri(resolver._reverse_with_prefix(view, prefix, *args, **kwargs)))
  File "C:\Python27\lib\site-packages\django-1.8.14-py2.7.egg\django\core\urlresolvers.py", line 495, in _reverse_with_prefix
    (lookup_view_s, args, kwargs, len(patterns), patterns))
NoReverseMatch: Reverse for 'prod_list_by_category' with arguments '()' and keyword arguments '{u'category': u'yagao'}' not found. 1 pattern(s) tried: ['prod_list/(?P<category>\\s+)']
[2017-01-13 15:52:23,687] [Thread-7:5048] [django.request:256] [base:handle_uncaught_exception] [ERROR]- Internal Server Error: /
Traceback (most recent call last):
  File "C:\Python27\lib\site-packages\django-1.8.14-py2.7.egg\django\core\handlers\base.py", line 132, in get_response
    response = wrapped_callback(request, *callback_args, **callback_kwargs)
  File "D:\PycharmProjects\fec\apps\ec\views.py", line 33, in get_prod_list
    context_dict)
  File "C:\Python27\lib\site-packages\django-1.8.14-py2.7.egg\django\shortcuts.py", line 67, in render
    template_name, context, request=request, using=using)
  File "C:\Python27\lib\site-packages\django-1.8.14-py2.7.egg\django\template\loader.py", line 99, in render_to_string
    return template.render(context, request)
  File "C:\Python27\lib\site-packages\django-1.8.14-py2.7.egg\django\template\backends\django.py", line 74, in render
    return self.template.render(context)
  File "C:\Python27\lib\site-packages\django-1.8.14-py2.7.egg\django\template\base.py", line 210, in render
    return self._render(context)
  File "C:\Python27\lib\site-packages\django-1.8.14-py2.7.egg\django\template\base.py", line 202, in _render
    return self.nodelist.render(context)
  File "C:\Python27\lib\site-packages\django-1.8.14-py2.7.egg\django\template\base.py", line 905, in render
    bit = self.render_node(node, context)
  File "C:\Python27\lib\site-packages\django-1.8.14-py2.7.egg\django\template\debug.py", line 79, in render_node
    return node.render(context)
  File "C:\Python27\lib\site-packages\django-1.8.14-py2.7.egg\django\template\loader_tags.py", line 135, in render
    return compiled_parent._render(context)
  File "C:\Python27\lib\site-packages\django-1.8.14-py2.7.egg\django\template\base.py", line 202, in _render
    return self.nodelist.render(context)
  File "C:\Python27\lib\site-packages\django-1.8.14-py2.7.egg\django\template\base.py", line 905, in render
    bit = self.render_node(node, context)
  File "C:\Python27\lib\site-packages\django-1.8.14-py2.7.egg\django\template\debug.py", line 79, in render_node
    return node.render(context)
  File "C:\Python27\lib\site-packages\django-1.8.14-py2.7.egg\django\template\loader_tags.py", line 135, in render
    return compiled_parent._render(context)
  File "C:\Python27\lib\site-packages\django-1.8.14-py2.7.egg\django\template\base.py", line 202, in _render
    return self.nodelist.render(context)
  File "C:\Python27\lib\site-packages\django-1.8.14-py2.7.egg\django\template\base.py", line 905, in render
    bit = self.render_node(node, context)
  File "C:\Python27\lib\site-packages\django-1.8.14-py2.7.egg\django\template\debug.py", line 79, in render_node
    return node.render(context)
  File "C:\Python27\lib\site-packages\django-1.8.14-py2.7.egg\django\template\loader_tags.py", line 65, in render
    result = block.nodelist.render(context)
  File "C:\Python27\lib\site-packages\django-1.8.14-py2.7.egg\django\template\base.py", line 905, in render
    bit = self.render_node(node, context)
  File "C:\Python27\lib\site-packages\django-1.8.14-py2.7.egg\django\template\debug.py", line 79, in render_node
    return node.render(context)
  File "C:\Python27\lib\site-packages\django-1.8.14-py2.7.egg\django\template\loader_tags.py", line 159, in render
    return template.render(context)
  File "C:\Python27\lib\site-packages\django-1.8.14-py2.7.egg\django\template\base.py", line 212, in render
    return self._render(context)
  File "C:\Python27\lib\site-packages\django-1.8.14-py2.7.egg\django\template\base.py", line 202, in _render
    return self.nodelist.render(context)
  File "C:\Python27\lib\site-packages\django-1.8.14-py2.7.egg\django\template\base.py", line 905, in render
    bit = self.render_node(node, context)
  File "C:\Python27\lib\site-packages\django-1.8.14-py2.7.egg\django\template\debug.py", line 79, in render_node
    return node.render(context)
  File "C:\Python27\lib\site-packages\django-1.8.14-py2.7.egg\django\template\defaulttags.py", line 507, in render
    six.reraise(*exc_info)
  File "C:\Python27\lib\site-packages\django-1.8.14-py2.7.egg\django\template\defaulttags.py", line 493, in render
    url = reverse(view_name, args=args, kwargs=kwargs, current_app=current_app)
  File "C:\Python27\lib\site-packages\django-1.8.14-py2.7.egg\django\core\urlresolvers.py", line 578, in reverse
    return force_text(iri_to_uri(resolver._reverse_with_prefix(view, prefix, *args, **kwargs)))
  File "C:\Python27\lib\site-packages\django-1.8.14-py2.7.egg\django\core\urlresolvers.py", line 495, in _reverse_with_prefix
    (lookup_view_s, args, kwargs, len(patterns), patterns))
NoReverseMatch: Reverse for 'prod_list_by_category' with arguments '()' and keyword arguments '{u'category': u'yagao'}' not found. 1 pattern(s) tried: ['prod_list/(?P<category>\\s+)']
[2017-01-13 16:05:31,423] [Thread-3:1456] [django.request:256] [base:handle_uncaught_exception] [ERROR]- Internal Server Error: /prod_list/yagao/
Traceback (most recent call last):
  File "C:\Python27\lib\site-packages\django-1.8.14-py2.7.egg\django\core\handlers\base.py", line 132, in get_response
    response = wrapped_callback(request, *callback_args, **callback_kwargs)
  File "D:\PycharmProjects\fec\apps\ec\views.py", line 39, in get_prod_list_by_category
    logger.debug('鏍规嵁鍟嗗搧绫诲瀷' + category + '鏌ヨ璇ョ被鍨嬫墍鏈夊晢鍝佷俊鎭?)
UnicodeDecodeError: 'ascii' codec can't decode byte 0xe6 in position 0: ordinal not in range(128)
